[2025-04-01T04:01:40.915+0000] {local_task_job_runner.py:120} INFO - ::group::Pre task execution logs
[2025-04-01T04:01:40.981+0000] {taskinstance.py:2073} INFO - Dependencies all met for dep_context=non-requeueable deps ti=<TaskInstance: clean_transform_data.transform_data manual__2025-04-01T04:01:33.256245+00:00 [queued]>
[2025-04-01T04:01:41.001+0000] {taskinstance.py:2073} INFO - Dependencies all met for dep_context=requeueable deps ti=<TaskInstance: clean_transform_data.transform_data manual__2025-04-01T04:01:33.256245+00:00 [queued]>
[2025-04-01T04:01:41.002+0000] {taskinstance.py:2303} INFO - Starting attempt 1 of 2
[2025-04-01T04:01:41.035+0000] {taskinstance.py:2327} INFO - Executing <Task(PythonOperator): transform_data> on 2025-04-01 04:01:33.256245+00:00
[2025-04-01T04:01:41.066+0000] {standard_task_runner.py:63} INFO - Started process 129 to run task
[2025-04-01T04:01:41.091+0000] {standard_task_runner.py:90} INFO - Running: ['***', 'tasks', 'run', 'clean_transform_data', 'transform_data', 'manual__2025-04-01T04:01:33.256245+00:00', '--job-id', '590', '--raw', '--subdir', 'DAGS_FOLDER/preprocess_data.py', '--cfg-path', '/tmp/tmpsz5l776v']
[2025-04-01T04:01:41.100+0000] {standard_task_runner.py:91} INFO - Job 590: Subtask transform_data
[2025-04-01T04:01:41.265+0000] {task_command.py:426} INFO - Running <TaskInstance: clean_transform_data.transform_data manual__2025-04-01T04:01:33.256245+00:00 [running]> on host d34402ef6e0d
[2025-04-01T04:01:41.521+0000] {taskinstance.py:2644} INFO - Exporting env vars: AIRFLOW_CTX_DAG_OWNER='***' AIRFLOW_CTX_DAG_ID='clean_transform_data' AIRFLOW_CTX_TASK_ID='transform_data' AIRFLOW_CTX_EXECUTION_DATE='2025-04-01T04:01:33.256245+00:00' AIRFLOW_CTX_TRY_NUMBER='1' AIRFLOW_CTX_DAG_RUN_ID='manual__2025-04-01T04:01:33.256245+00:00'
[2025-04-01T04:01:41.522+0000] {taskinstance.py:430} INFO - ::endgroup::
[2025-04-01T04:01:41.572+0000] {base.py:84} INFO - Using connection ID 'mysql_***_conn' for task execution.
[2025-04-01T04:01:41.587+0000] {base.py:84} INFO - Using connection ID 'mysql_***_conn' for task execution.
[2025-04-01T04:01:41.608+0000] {warnings.py:109} WARNING - /home/***/.local/lib/python3.8/site-packages/***/providers/common/sql/hooks/sql.py:227: UserWarning: pandas only supports SQLAlchemy connectable (engine/connection) or database string URI or sqlite3 DBAPI2 connection. Other DBAPI2 objects are not tested. Please consider using SQLAlchemy.
  return psql.read_sql(sql, con=conn, params=parameters, **kwargs)

[2025-04-01T04:01:41.717+0000] {taskinstance.py:441} INFO - ::group::Post task execution logs
[2025-04-01T04:01:41.718+0000] {taskinstance.py:2890} ERROR - Task failed with exception
Traceback (most recent call last):
  File "/home/airflow/.local/lib/python3.8/site-packages/airflow/models/taskinstance.py", line 465, in _execute_task
    result = _execute_callable(context=context, **execute_callable_kwargs)
  File "/home/airflow/.local/lib/python3.8/site-packages/airflow/models/taskinstance.py", line 432, in _execute_callable
    return execute_callable(context=context, **execute_callable_kwargs)
  File "/home/airflow/.local/lib/python3.8/site-packages/airflow/models/baseoperator.py", line 400, in wrapper
    return func(self, *args, **kwargs)
  File "/home/airflow/.local/lib/python3.8/site-packages/airflow/operators/python.py", line 235, in execute
    return_value = self.execute_callable()
  File "/home/airflow/.local/lib/python3.8/site-packages/airflow/operators/python.py", line 252, in execute_callable
    return self.python_callable(*self.op_args, **self.op_kwargs)
  File "/opt/airflow/dags/preprocess_data.py", line 46, in clean_transform_data
    df[variables_continuas] = scaler.fit_transform(df[variables_continuas])
  File "/home/airflow/.local/lib/python3.8/site-packages/sklearn/utils/_set_output.py", line 157, in wrapped
    data_to_wrap = f(self, X, *args, **kwargs)
  File "/home/airflow/.local/lib/python3.8/site-packages/sklearn/base.py", line 916, in fit_transform
    return self.fit(X, **fit_params).transform(X)
  File "/home/airflow/.local/lib/python3.8/site-packages/sklearn/preprocessing/_data.py", line 435, in fit
    return self.partial_fit(X, y)
  File "/home/airflow/.local/lib/python3.8/site-packages/sklearn/base.py", line 1152, in wrapper
    return fit_method(estimator, *args, **kwargs)
  File "/home/airflow/.local/lib/python3.8/site-packages/sklearn/preprocessing/_data.py", line 473, in partial_fit
    X = self._validate_data(
  File "/home/airflow/.local/lib/python3.8/site-packages/sklearn/base.py", line 605, in _validate_data
    out = check_array(X, input_name="X", **check_params)
  File "/home/airflow/.local/lib/python3.8/site-packages/sklearn/utils/validation.py", line 967, in check_array
    raise ValueError(
ValueError: Found array with 0 sample(s) (shape=(0, 11)) while a minimum of 1 is required by MinMaxScaler.
[2025-04-01T04:01:41.766+0000] {taskinstance.py:1205} INFO - Marking task as UP_FOR_RETRY. dag_id=clean_transform_data, task_id=transform_data, execution_date=20250401T040133, start_date=20250401T040140, end_date=20250401T040141
[2025-04-01T04:01:41.808+0000] {standard_task_runner.py:110} ERROR - Failed to execute job 590 for task transform_data (Found array with 0 sample(s) (shape=(0, 11)) while a minimum of 1 is required by MinMaxScaler.; 129)
[2025-04-01T04:01:41.881+0000] {local_task_job_runner.py:240} INFO - Task exited with return code 1
[2025-04-01T04:01:41.941+0000] {taskinstance.py:3482} INFO - 0 downstream tasks scheduled from follow-on schedule check
[2025-04-01T04:01:41.944+0000] {local_task_job_runner.py:222} INFO - ::endgroup::
