[2025-05-01T03:38:05.137+0000] {local_task_job_runner.py:120} INFO - ::group::Pre task execution logs
[2025-05-01T03:38:05.185+0000] {taskinstance.py:2073} INFO - Dependencies all met for dep_context=non-requeueable deps ti=<TaskInstance: fetch_and_store_diabetes_data.get_dataset_info manual__2025-05-01T03:38:01.898931+00:00 [queued]>
[2025-05-01T03:38:05.210+0000] {taskinstance.py:2073} INFO - Dependencies all met for dep_context=requeueable deps ti=<TaskInstance: fetch_and_store_diabetes_data.get_dataset_info manual__2025-05-01T03:38:01.898931+00:00 [queued]>
[2025-05-01T03:38:05.210+0000] {taskinstance.py:2303} INFO - Starting attempt 1 of 4
[2025-05-01T03:38:05.239+0000] {taskinstance.py:2327} INFO - Executing <Task(PythonOperator): get_dataset_info> on 2025-05-01 03:38:01.898931+00:00
[2025-05-01T03:38:05.267+0000] {standard_task_runner.py:63} INFO - Started process 306 to run task
[2025-05-01T03:38:05.281+0000] {standard_task_runner.py:90} INFO - Running: ['***', 'tasks', 'run', 'fetch_and_store_diabetes_data', 'get_dataset_info', 'manual__2025-05-01T03:38:01.898931+00:00', '--job-id', '23', '--raw', '--subdir', 'DAGS_FOLDER/fetch_and_store_data.py', '--cfg-path', '/tmp/tmpq95crm0g']
[2025-05-01T03:38:05.288+0000] {standard_task_runner.py:91} INFO - Job 23: Subtask get_dataset_info
[2025-05-01T03:38:05.393+0000] {task_command.py:426} INFO - Running <TaskInstance: fetch_and_store_diabetes_data.get_dataset_info manual__2025-05-01T03:38:01.898931+00:00 [running]> on host 88e291e8513c
[2025-05-01T03:38:05.520+0000] {taskinstance.py:2644} INFO - Exporting env vars: AIRFLOW_CTX_DAG_OWNER='***' AIRFLOW_CTX_DAG_ID='fetch_and_store_diabetes_data' AIRFLOW_CTX_TASK_ID='get_dataset_info' AIRFLOW_CTX_EXECUTION_DATE='2025-05-01T03:38:01.898931+00:00' AIRFLOW_CTX_TRY_NUMBER='1' AIRFLOW_CTX_DAG_RUN_ID='manual__2025-05-01T03:38:01.898931+00:00'
[2025-05-01T03:38:05.521+0000] {taskinstance.py:430} INFO - ::endgroup::
[2025-05-01T03:38:05.554+0000] {fetch_and_store_data.py:61} ERROR - Error al obtener informaci√≥n del dataset: HTTPConnectionPool(host='datapi', port=8000): Max retries exceeded with url: /dataset-info (Caused by NewConnectionError('<urllib3.connection.HTTPConnection object at 0x7c47b1fc78b0>: Failed to establish a new connection: [Errno 111] Connection refused'))
[2025-05-01T03:38:05.554+0000] {taskinstance.py:441} INFO - ::group::Post task execution logs
[2025-05-01T03:38:05.555+0000] {taskinstance.py:2890} ERROR - Task failed with exception
Traceback (most recent call last):
  File "/home/airflow/.local/lib/python3.8/site-packages/urllib3/connection.py", line 174, in _new_conn
    conn = connection.create_connection(
  File "/home/airflow/.local/lib/python3.8/site-packages/urllib3/util/connection.py", line 95, in create_connection
    raise err
  File "/home/airflow/.local/lib/python3.8/site-packages/urllib3/util/connection.py", line 85, in create_connection
    sock.connect(sa)
ConnectionRefusedError: [Errno 111] Connection refused

During handling of the above exception, another exception occurred:

Traceback (most recent call last):
  File "/home/airflow/.local/lib/python3.8/site-packages/urllib3/connectionpool.py", line 715, in urlopen
    httplib_response = self._make_request(
  File "/home/airflow/.local/lib/python3.8/site-packages/urllib3/connectionpool.py", line 416, in _make_request
    conn.request(method, url, **httplib_request_kw)
  File "/home/airflow/.local/lib/python3.8/site-packages/urllib3/connection.py", line 244, in request
    super(HTTPConnection, self).request(method, url, body=body, headers=headers)
  File "/usr/local/lib/python3.8/http/client.py", line 1256, in request
    self._send_request(method, url, body, headers, encode_chunked)
  File "/usr/local/lib/python3.8/http/client.py", line 1302, in _send_request
    self.endheaders(body, encode_chunked=encode_chunked)
  File "/usr/local/lib/python3.8/http/client.py", line 1251, in endheaders
    self._send_output(message_body, encode_chunked=encode_chunked)
  File "/usr/local/lib/python3.8/http/client.py", line 1011, in _send_output
    self.send(msg)
  File "/usr/local/lib/python3.8/http/client.py", line 951, in send
    self.connect()
  File "/home/airflow/.local/lib/python3.8/site-packages/urllib3/connection.py", line 205, in connect
    conn = self._new_conn()
  File "/home/airflow/.local/lib/python3.8/site-packages/urllib3/connection.py", line 186, in _new_conn
    raise NewConnectionError(
urllib3.exceptions.NewConnectionError: <urllib3.connection.HTTPConnection object at 0x7c47b1fc78b0>: Failed to establish a new connection: [Errno 111] Connection refused

During handling of the above exception, another exception occurred:

Traceback (most recent call last):
  File "/home/airflow/.local/lib/python3.8/site-packages/requests/adapters.py", line 486, in send
    resp = conn.urlopen(
  File "/home/airflow/.local/lib/python3.8/site-packages/urllib3/connectionpool.py", line 799, in urlopen
    retries = retries.increment(
  File "/home/airflow/.local/lib/python3.8/site-packages/urllib3/util/retry.py", line 592, in increment
    raise MaxRetryError(_pool, url, error or ResponseError(cause))
urllib3.exceptions.MaxRetryError: HTTPConnectionPool(host='datapi', port=8000): Max retries exceeded with url: /dataset-info (Caused by NewConnectionError('<urllib3.connection.HTTPConnection object at 0x7c47b1fc78b0>: Failed to establish a new connection: [Errno 111] Connection refused'))

During handling of the above exception, another exception occurred:

Traceback (most recent call last):
  File "/home/airflow/.local/lib/python3.8/site-packages/airflow/models/taskinstance.py", line 465, in _execute_task
    result = _execute_callable(context=context, **execute_callable_kwargs)
  File "/home/airflow/.local/lib/python3.8/site-packages/airflow/models/taskinstance.py", line 432, in _execute_callable
    return execute_callable(context=context, **execute_callable_kwargs)
  File "/home/airflow/.local/lib/python3.8/site-packages/airflow/models/baseoperator.py", line 400, in wrapper
    return func(self, *args, **kwargs)
  File "/home/airflow/.local/lib/python3.8/site-packages/airflow/operators/python.py", line 235, in execute
    return_value = self.execute_callable()
  File "/home/airflow/.local/lib/python3.8/site-packages/airflow/operators/python.py", line 252, in execute_callable
    return self.python_callable(*self.op_args, **self.op_kwargs)
  File "/opt/airflow/dags/fetch_and_store_data.py", line 45, in get_dataset_info
    response = requests.get(f"{API_BASE_URL}/dataset-info")
  File "/home/airflow/.local/lib/python3.8/site-packages/requests/api.py", line 73, in get
    return request("get", url, params=params, **kwargs)
  File "/home/airflow/.local/lib/python3.8/site-packages/requests/api.py", line 59, in request
    return session.request(method=method, url=url, **kwargs)
  File "/home/airflow/.local/lib/python3.8/site-packages/requests/sessions.py", line 589, in request
    resp = self.send(prep, **send_kwargs)
  File "/home/airflow/.local/lib/python3.8/site-packages/requests/sessions.py", line 703, in send
    r = adapter.send(request, **kwargs)
  File "/home/airflow/.local/lib/python3.8/site-packages/requests/adapters.py", line 519, in send
    raise ConnectionError(e, request=request)
requests.exceptions.ConnectionError: HTTPConnectionPool(host='datapi', port=8000): Max retries exceeded with url: /dataset-info (Caused by NewConnectionError('<urllib3.connection.HTTPConnection object at 0x7c47b1fc78b0>: Failed to establish a new connection: [Errno 111] Connection refused'))
[2025-05-01T03:38:05.623+0000] {taskinstance.py:1205} INFO - Marking task as UP_FOR_RETRY. dag_id=fetch_and_store_diabetes_data, task_id=get_dataset_info, execution_date=20250501T033801, start_date=20250501T033805, end_date=20250501T033805
[2025-05-01T03:38:05.674+0000] {standard_task_runner.py:110} ERROR - Failed to execute job 23 for task get_dataset_info (HTTPConnectionPool(host='datapi', port=8000): Max retries exceeded with url: /dataset-info (Caused by NewConnectionError('<urllib3.connection.HTTPConnection object at 0x7c47b1fc78b0>: Failed to establish a new connection: [Errno 111] Connection refused')); 306)
[2025-05-01T03:38:05.742+0000] {local_task_job_runner.py:240} INFO - Task exited with return code 1
[2025-05-01T03:38:05.791+0000] {taskinstance.py:3482} INFO - 0 downstream tasks scheduled from follow-on schedule check
[2025-05-01T03:38:05.794+0000] {local_task_job_runner.py:222} INFO - ::endgroup::
