[2025-04-01T02:54:31.264+0000] {taskinstance.py:1125} INFO - Dependencies all met for dep_context=non-requeueable deps ti=<TaskInstance: train_model.train_model manual__2025-04-01T02:51:38.019676+00:00 [queued]>
[2025-04-01T02:54:31.311+0000] {taskinstance.py:1125} INFO - Dependencies all met for dep_context=requeueable deps ti=<TaskInstance: train_model.train_model manual__2025-04-01T02:51:38.019676+00:00 [queued]>
[2025-04-01T02:54:31.312+0000] {taskinstance.py:1331} INFO - Starting attempt 3 of 4
[2025-04-01T02:54:31.362+0000] {taskinstance.py:1350} INFO - Executing <Task(PythonOperator): train_model> on 2025-04-01 02:51:38.019676+00:00
[2025-04-01T02:54:31.405+0000] {standard_task_runner.py:57} INFO - Started process 27268 to run task
[2025-04-01T02:54:31.426+0000] {standard_task_runner.py:84} INFO - Running: ['***', 'tasks', 'run', 'train_model', 'train_model', 'manual__2025-04-01T02:51:38.019676+00:00', '--job-id', '575', '--raw', '--subdir', 'DAGS_FOLDER/train.py', '--cfg-path', '/tmp/tmp0wm8sdx9']
[2025-04-01T02:54:31.434+0000] {standard_task_runner.py:85} INFO - Job 575: Subtask train_model
[2025-04-01T02:54:31.607+0000] {task_command.py:410} INFO - Running <TaskInstance: train_model.train_model manual__2025-04-01T02:51:38.019676+00:00 [running]> on host 76e1807f7118
[2025-04-01T02:54:31.809+0000] {taskinstance.py:1570} INFO - Exporting env vars: AIRFLOW_CTX_DAG_OWNER='***' AIRFLOW_CTX_DAG_ID='train_model' AIRFLOW_CTX_TASK_ID='train_model' AIRFLOW_CTX_EXECUTION_DATE='2025-04-01T02:51:38.019676+00:00' AIRFLOW_CTX_TRY_NUMBER='3' AIRFLOW_CTX_DAG_RUN_ID='manual__2025-04-01T02:51:38.019676+00:00'
[2025-04-01T02:54:31.812+0000] {logging_mixin.py:149} INFO - MLflow Version: 1.30.1
[2025-04-01T02:54:31.833+0000] {base.py:73} INFO - Using connection ID 'mysql_***_conn' for task execution.
[2025-04-01T02:54:32.576+0000] {logging_mixin.py:149} WARNING - 2025/04/01 02:54:32 WARNING mlflow.utils.git_utils: Failed to import Git (the Git executable is probably not on your PATH), so Git SHA is not available. Error: Failed to initialize: Bad git executable.
The git executable must be specified in one of the following ways:
    - be included in your $PATH
    - be set via $GIT_PYTHON_GIT_EXECUTABLE
    - explicitly set via git.refresh(<full-path-to-git-executable>)

All git commands will error until this is rectified.

This initial message can be silenced or aggravated in the future by setting the
$GIT_PYTHON_REFRESH environment variable. Use one of the following values:
    - quiet|q|silence|s|silent|none|n|0: for no message or exception
    - warn|w|warning|log|l|1: for a warning message (logging level CRITICAL, displayed by default)
    - error|e|exception|raise|r|2: for a raised exception

Example:
    export GIT_PYTHON_REFRESH=quiet
[2025-04-01T02:54:32.701+0000] {warnings.py:110} WARNING - /home/***/.local/lib/python3.7/site-packages/joblib/parallel.py:736: UserWarning: Loky-backed parallel loops cannot be called in a multiprocessing, setting n_jobs=1
  **self._backend_args)

[2025-04-01T02:54:45.020+0000] {warnings.py:110} WARNING - /home/***/.local/lib/python3.7/site-packages/_distutils_hack/__init__.py:33: UserWarning: Setuptools is replacing distutils.
  warnings.warn("Setuptools is replacing distutils.")

[2025-04-01T02:54:45.140+0000] {credentials.py:1123} INFO - Found credentials in environment variables.
[2025-04-01T02:54:48.278+0000] {taskinstance.py:1847} ERROR - Task failed with exception
Traceback (most recent call last):
  File "/home/airflow/.local/lib/python3.7/site-packages/airflow/operators/python.py", line 181, in execute
    return_value = self.execute_callable()
  File "/home/airflow/.local/lib/python3.7/site-packages/airflow/operators/python.py", line 198, in execute_callable
    return self.python_callable(*self.op_args, **self.op_kwargs)
  File "/opt/airflow/dags/train.py", line 86, in train_model
    registered_model_name="svm-model"
  File "/home/airflow/.local/lib/python3.7/site-packages/mlflow/sklearn/__init__.py", line 420, in log_model
    pyfunc_predict_fn=pyfunc_predict_fn,
  File "/home/airflow/.local/lib/python3.7/site-packages/mlflow/models/model.py", line 387, in log
    await_registration_for=await_registration_for,
  File "/home/airflow/.local/lib/python3.7/site-packages/mlflow/tracking/_model_registry/fluent.py", line 74, in register_model
    raise e
  File "/home/airflow/.local/lib/python3.7/site-packages/mlflow/tracking/_model_registry/fluent.py", line 65, in register_model
    create_model_response = client.create_registered_model(name)
  File "/home/airflow/.local/lib/python3.7/site-packages/mlflow/tracking/client.py", line 1847, in create_registered_model
    return self._get_registry_client().create_registered_model(name, tags, description)
  File "/home/airflow/.local/lib/python3.7/site-packages/mlflow/tracking/_model_registry/client.py", line 59, in create_registered_model
    return self.store.create_registered_model(name, tags, description)
  File "/home/airflow/.local/lib/python3.7/site-packages/mlflow/store/model_registry/rest_store.py", line 83, in create_registered_model
    response_proto = self._call_endpoint(CreateRegisteredModel, req_body)
  File "/home/airflow/.local/lib/python3.7/site-packages/mlflow/store/model_registry/rest_store.py", line 64, in _call_endpoint
    return call_endpoint(self.get_host_creds(), endpoint, method, json_body, response_proto)
  File "/home/airflow/.local/lib/python3.7/site-packages/mlflow/utils/rest_utils.py", line 280, in call_endpoint
    response = verify_rest_response(response, endpoint)
  File "/home/airflow/.local/lib/python3.7/site-packages/mlflow/utils/rest_utils.py", line 214, in verify_rest_response
    error_code=get_error_code(response.status_code),
mlflow.exceptions.MlflowException: API request to endpoint /api/2.0/preview/mlflow/registered-models/create failed with error code 404 != 200. Response body: '<!doctype html>
<html lang=en>
<title>404 Not Found</title>
<h1>Not Found</h1>
<p>The requested URL was not found on the server. If you entered the URL manually please check your spelling and try again.</p>
'
[2025-04-01T02:54:48.353+0000] {taskinstance.py:1373} INFO - Marking task as UP_FOR_RETRY. dag_id=train_model, task_id=train_model, execution_date=20250401T025138, start_date=20250401T025431, end_date=20250401T025448
[2025-04-01T02:54:48.406+0000] {standard_task_runner.py:109} ERROR - Failed to execute job 575 for task train_model (API request to endpoint /api/2.0/preview/mlflow/registered-models/create failed with error code 404 != 200. Response body: '<!doctype html>
<html lang=en>
<title>404 Not Found</title>
<h1>Not Found</h1>
<p>The requested URL was not found on the server. If you entered the URL manually please check your spelling and try again.</p>
'; 27268)
[2025-04-01T02:54:48.575+0000] {local_task_job_runner.py:232} INFO - Task exited with return code 1
[2025-04-01T02:54:48.694+0000] {taskinstance.py:2674} INFO - 0 downstream tasks scheduled from follow-on schedule check
