[2025-03-31T00:20:25.915+0000] {taskinstance.py:1125} INFO - Dependencies all met for dep_context=non-requeueable deps ti=<TaskInstance: train_model.train_model manual__2025-03-31T00:17:27.770249+00:00 [queued]>
[2025-03-31T00:20:25.953+0000] {taskinstance.py:1125} INFO - Dependencies all met for dep_context=requeueable deps ti=<TaskInstance: train_model.train_model manual__2025-03-31T00:17:27.770249+00:00 [queued]>
[2025-03-31T00:20:25.955+0000] {taskinstance.py:1331} INFO - Starting attempt 2 of 3
[2025-03-31T00:20:26.006+0000] {taskinstance.py:1350} INFO - Executing <Task(PythonOperator): train_model> on 2025-03-31 00:17:27.770249+00:00
[2025-03-31T00:20:26.047+0000] {standard_task_runner.py:57} INFO - Started process 433 to run task
[2025-03-31T00:20:26.056+0000] {standard_task_runner.py:84} INFO - Running: ['***', 'tasks', 'run', 'train_model', 'train_model', 'manual__2025-03-31T00:17:27.770249+00:00', '--job-id', '531', '--raw', '--subdir', 'DAGS_FOLDER/train.py', '--cfg-path', '/tmp/tmp1r4fyj6w']
[2025-03-31T00:20:26.078+0000] {standard_task_runner.py:85} INFO - Job 531: Subtask train_model
[2025-03-31T00:20:26.255+0000] {task_command.py:410} INFO - Running <TaskInstance: train_model.train_model manual__2025-03-31T00:17:27.770249+00:00 [running]> on host 76e1807f7118
[2025-03-31T00:20:26.457+0000] {taskinstance.py:1570} INFO - Exporting env vars: AIRFLOW_CTX_DAG_OWNER='***' AIRFLOW_CTX_DAG_ID='train_model' AIRFLOW_CTX_TASK_ID='train_model' AIRFLOW_CTX_EXECUTION_DATE='2025-03-31T00:17:27.770249+00:00' AIRFLOW_CTX_TRY_NUMBER='2' AIRFLOW_CTX_DAG_RUN_ID='manual__2025-03-31T00:17:27.770249+00:00'
[2025-03-31T00:20:26.495+0000] {base.py:73} INFO - Using connection ID 'mysql_***_conn' for task execution.
[2025-03-31T00:20:26.719+0000] {connectionpool.py:813} WARNING - Retrying (Retry(total=4, connect=4, read=5, redirect=5, status=5)) after connection broken by 'NewConnectionError('<urllib3.connection.HTTPConnection object at 0x7764c571a550>: Failed to establish a new connection: [Errno 111] Connection refused')': /api/2.0/mlflow/experiments/get-by-name?experiment_name=mlflow_tracking_examples_3
[2025-03-31T00:20:30.728+0000] {connectionpool.py:813} WARNING - Retrying (Retry(total=3, connect=3, read=5, redirect=5, status=5)) after connection broken by 'NewConnectionError('<urllib3.connection.HTTPConnection object at 0x7764c56e4910>: Failed to establish a new connection: [Errno 111] Connection refused')': /api/2.0/mlflow/experiments/get-by-name?experiment_name=mlflow_tracking_examples_3
[2025-03-31T00:20:38.738+0000] {connectionpool.py:813} WARNING - Retrying (Retry(total=2, connect=2, read=5, redirect=5, status=5)) after connection broken by 'NewConnectionError('<urllib3.connection.HTTPConnection object at 0x7764c56e4f10>: Failed to establish a new connection: [Errno 111] Connection refused')': /api/2.0/mlflow/experiments/get-by-name?experiment_name=mlflow_tracking_examples_3
[2025-03-31T00:20:54.758+0000] {connectionpool.py:813} WARNING - Retrying (Retry(total=1, connect=1, read=5, redirect=5, status=5)) after connection broken by 'NewConnectionError('<urllib3.connection.HTTPConnection object at 0x7764c569e8d0>: Failed to establish a new connection: [Errno 111] Connection refused')': /api/2.0/mlflow/experiments/get-by-name?experiment_name=mlflow_tracking_examples_3
[2025-03-31T00:21:26.795+0000] {connectionpool.py:813} WARNING - Retrying (Retry(total=0, connect=0, read=5, redirect=5, status=5)) after connection broken by 'NewConnectionError('<urllib3.connection.HTTPConnection object at 0x7764c569ef50>: Failed to establish a new connection: [Errno 111] Connection refused')': /api/2.0/mlflow/experiments/get-by-name?experiment_name=mlflow_tracking_examples_3
[2025-03-31T00:21:26.800+0000] {taskinstance.py:1847} ERROR - Task failed with exception
Traceback (most recent call last):
  File "/home/airflow/.local/lib/python3.7/site-packages/urllib3/connection.py", line 175, in _new_conn
    (self._dns_host, self.port), self.timeout, **extra_kw
  File "/home/airflow/.local/lib/python3.7/site-packages/urllib3/util/connection.py", line 95, in create_connection
    raise err
  File "/home/airflow/.local/lib/python3.7/site-packages/urllib3/util/connection.py", line 85, in create_connection
    sock.connect(sa)
ConnectionRefusedError: [Errno 111] Connection refused

During handling of the above exception, another exception occurred:

Traceback (most recent call last):
  File "/home/airflow/.local/lib/python3.7/site-packages/urllib3/connectionpool.py", line 710, in urlopen
    chunked=chunked,
  File "/home/airflow/.local/lib/python3.7/site-packages/urllib3/connectionpool.py", line 398, in _make_request
    conn.request(method, url, **httplib_request_kw)
  File "/home/airflow/.local/lib/python3.7/site-packages/urllib3/connection.py", line 244, in request
    super(HTTPConnection, self).request(method, url, body=body, headers=headers)
  File "/usr/local/lib/python3.7/http/client.py", line 1281, in request
    self._send_request(method, url, body, headers, encode_chunked)
  File "/usr/local/lib/python3.7/http/client.py", line 1327, in _send_request
    self.endheaders(body, encode_chunked=encode_chunked)
  File "/usr/local/lib/python3.7/http/client.py", line 1276, in endheaders
    self._send_output(message_body, encode_chunked=encode_chunked)
  File "/usr/local/lib/python3.7/http/client.py", line 1036, in _send_output
    self.send(msg)
  File "/usr/local/lib/python3.7/http/client.py", line 976, in send
    self.connect()
  File "/home/airflow/.local/lib/python3.7/site-packages/urllib3/connection.py", line 205, in connect
    conn = self._new_conn()
  File "/home/airflow/.local/lib/python3.7/site-packages/urllib3/connection.py", line 187, in _new_conn
    self, "Failed to establish a new connection: %s" % e
urllib3.exceptions.NewConnectionError: <urllib3.connection.HTTPConnection object at 0x7764c56aef50>: Failed to establish a new connection: [Errno 111] Connection refused

During handling of the above exception, another exception occurred:

Traceback (most recent call last):
  File "/home/airflow/.local/lib/python3.7/site-packages/requests/adapters.py", line 497, in send
    chunked=chunked,
  File "/home/airflow/.local/lib/python3.7/site-packages/urllib3/connectionpool.py", line 828, in urlopen
    **response_kw
  File "/home/airflow/.local/lib/python3.7/site-packages/urllib3/connectionpool.py", line 828, in urlopen
    **response_kw
  File "/home/airflow/.local/lib/python3.7/site-packages/urllib3/connectionpool.py", line 828, in urlopen
    **response_kw
  [Previous line repeated 2 more times]
  File "/home/airflow/.local/lib/python3.7/site-packages/urllib3/connectionpool.py", line 788, in urlopen
    method, url, error=e, _pool=self, _stacktrace=sys.exc_info()[2]
  File "/home/airflow/.local/lib/python3.7/site-packages/urllib3/util/retry.py", line 592, in increment
    raise MaxRetryError(_pool, url, error or ResponseError(cause))
urllib3.exceptions.MaxRetryError: HTTPConnectionPool(host='mlflow', port=5001): Max retries exceeded with url: /api/2.0/mlflow/experiments/get-by-name?experiment_name=mlflow_tracking_examples_3 (Caused by NewConnectionError('<urllib3.connection.HTTPConnection object at 0x7764c56aef50>: Failed to establish a new connection: [Errno 111] Connection refused'))

During handling of the above exception, another exception occurred:

Traceback (most recent call last):
  File "/home/airflow/.local/lib/python3.7/site-packages/mlflow/utils/rest_utils.py", line 175, in http_request
    **kwargs,
  File "/home/airflow/.local/lib/python3.7/site-packages/mlflow/utils/rest_utils.py", line 97, in _get_http_response_with_retries
    return session.request(method, url, **kwargs)
  File "/home/airflow/.local/lib/python3.7/site-packages/requests/sessions.py", line 589, in request
    resp = self.send(prep, **send_kwargs)
  File "/home/airflow/.local/lib/python3.7/site-packages/requests/sessions.py", line 703, in send
    r = adapter.send(request, **kwargs)
  File "/home/airflow/.local/lib/python3.7/site-packages/requests/adapters.py", line 519, in send
    raise ConnectionError(e, request=request)
requests.exceptions.ConnectionError: HTTPConnectionPool(host='mlflow', port=5001): Max retries exceeded with url: /api/2.0/mlflow/experiments/get-by-name?experiment_name=mlflow_tracking_examples_3 (Caused by NewConnectionError('<urllib3.connection.HTTPConnection object at 0x7764c56aef50>: Failed to establish a new connection: [Errno 111] Connection refused'))

During handling of the above exception, another exception occurred:

Traceback (most recent call last):
  File "/home/airflow/.local/lib/python3.7/site-packages/airflow/operators/python.py", line 181, in execute
    return_value = self.execute_callable()
  File "/home/airflow/.local/lib/python3.7/site-packages/airflow/operators/python.py", line 198, in execute_callable
    return self.python_callable(*self.op_args, **self.op_kwargs)
  File "/opt/airflow/dags/train.py", line 58, in train_model
    experiment = mlflow.get_experiment_by_name(experiment_name)
  File "/home/airflow/.local/lib/python3.7/site-packages/mlflow/tracking/fluent.py", line 1052, in get_experiment_by_name
    return MlflowClient().get_experiment_by_name(name)
  File "/home/airflow/.local/lib/python3.7/site-packages/mlflow/tracking/client.py", line 585, in get_experiment_by_name
    return self._tracking_client.get_experiment_by_name(name)
  File "/home/airflow/.local/lib/python3.7/site-packages/mlflow/tracking/_tracking_service/client.py", line 241, in get_experiment_by_name
    return self.store.get_experiment_by_name(name)
  File "/home/airflow/.local/lib/python3.7/site-packages/mlflow/store/tracking/rest_store.py", line 332, in get_experiment_by_name
    raise e
  File "/home/airflow/.local/lib/python3.7/site-packages/mlflow/store/tracking/rest_store.py", line 319, in get_experiment_by_name
    response_proto = self._call_endpoint(GetExperimentByName, req_body)
  File "/home/airflow/.local/lib/python3.7/site-packages/mlflow/store/tracking/rest_store.py", line 57, in _call_endpoint
    return call_endpoint(self.get_host_creds(), endpoint, method, json_body, response_proto)
  File "/home/airflow/.local/lib/python3.7/site-packages/mlflow/utils/rest_utils.py", line 274, in call_endpoint
    host_creds=host_creds, endpoint=endpoint, method=method, params=json_body
  File "/home/airflow/.local/lib/python3.7/site-packages/mlflow/utils/rest_utils.py", line 184, in http_request
    raise MlflowException("API request to %s failed with exception %s" % (url, e))
mlflow.exceptions.MlflowException: API request to http://mlflow:5001/api/2.0/mlflow/experiments/get-by-name failed with exception HTTPConnectionPool(host='mlflow', port=5001): Max retries exceeded with url: /api/2.0/mlflow/experiments/get-by-name?experiment_name=mlflow_tracking_examples_3 (Caused by NewConnectionError('<urllib3.connection.HTTPConnection object at 0x7764c56aef50>: Failed to establish a new connection: [Errno 111] Connection refused'))
[2025-03-31T00:21:26.938+0000] {taskinstance.py:1373} INFO - Marking task as UP_FOR_RETRY. dag_id=train_model, task_id=train_model, execution_date=20250331T001727, start_date=20250331T002025, end_date=20250331T002126
[2025-03-31T00:21:27.036+0000] {standard_task_runner.py:109} ERROR - Failed to execute job 531 for task train_model (API request to http://mlflow:5001/api/2.0/mlflow/experiments/get-by-name failed with exception HTTPConnectionPool(host='mlflow', port=5001): Max retries exceeded with url: /api/2.0/mlflow/experiments/get-by-name?experiment_name=mlflow_tracking_examples_3 (Caused by NewConnectionError('<urllib3.connection.HTTPConnection object at 0x7764c56aef50>: Failed to establish a new connection: [Errno 111] Connection refused')); 433)
[2025-03-31T00:21:27.125+0000] {local_task_job_runner.py:232} INFO - Task exited with return code 1
[2025-03-31T00:21:27.170+0000] {taskinstance.py:2674} INFO - 0 downstream tasks scheduled from follow-on schedule check
