[2025-03-10T00:05:15.627+0000] {taskinstance.py:1125} INFO - Dependencies all met for dep_context=non-requeueable deps ti=<TaskInstance: dag_maestro.load_csv_to_mysql manual__2025-03-09T23:56:29.581975+00:00 [queued]>
[2025-03-10T00:05:15.678+0000] {taskinstance.py:1125} INFO - Dependencies all met for dep_context=requeueable deps ti=<TaskInstance: dag_maestro.load_csv_to_mysql manual__2025-03-09T23:56:29.581975+00:00 [queued]>
[2025-03-10T00:05:15.678+0000] {taskinstance.py:1331} INFO - Starting attempt 1 of 2
[2025-03-10T00:05:15.807+0000] {taskinstance.py:1350} INFO - Executing <Task(TriggerDagRunOperator): load_csv_to_mysql> on 2025-03-09 23:56:29.581975+00:00
[2025-03-10T00:05:15.832+0000] {standard_task_runner.py:57} INFO - Started process 678 to run task
[2025-03-10T00:05:15.867+0000] {standard_task_runner.py:84} INFO - Running: ['***', 'tasks', 'run', 'dag_maestro', 'load_csv_to_mysql', 'manual__2025-03-09T23:56:29.581975+00:00', '--job-id', '18', '--raw', '--subdir', 'DAGS_FOLDER/orchestrator.py', '--cfg-path', '/tmp/tmpauexa37c']
[2025-03-10T00:05:15.871+0000] {standard_task_runner.py:85} INFO - Job 18: Subtask load_csv_to_mysql
[2025-03-10T00:05:16.473+0000] {task_command.py:410} INFO - Running <TaskInstance: dag_maestro.load_csv_to_mysql manual__2025-03-09T23:56:29.581975+00:00 [running]> on host d7c1c9924032
[2025-03-10T00:05:17.587+0000] {taskinstance.py:1570} INFO - Exporting env vars: AIRFLOW_CTX_DAG_OWNER='***' AIRFLOW_CTX_DAG_ID='dag_maestro' AIRFLOW_CTX_TASK_ID='load_csv_to_mysql' AIRFLOW_CTX_EXECUTION_DATE='2025-03-09T23:56:29.581975+00:00' AIRFLOW_CTX_TRY_NUMBER='1' AIRFLOW_CTX_DAG_RUN_ID='manual__2025-03-09T23:56:29.581975+00:00'
[2025-03-10T00:05:17.805+0000] {taskinstance.py:1847} ERROR - Task failed with exception
Traceback (most recent call last):
  File "/home/airflow/.local/lib/python3.7/site-packages/airflow/operators/trigger_dagrun.py", line 155, in execute
    replace_microseconds=False,
  File "/home/airflow/.local/lib/python3.7/site-packages/airflow/api/common/trigger_dag.py", line 128, in trigger_dag
    replace_microseconds=replace_microseconds,
  File "/home/airflow/.local/lib/python3.7/site-packages/airflow/api/common/trigger_dag.py", line 52, in _trigger_dag
    raise DagNotFound(f"Dag id {dag_id} not found")
airflow.exceptions.DagNotFound: Dag id crear_tabla_mysql not found
[2025-03-10T00:05:17.851+0000] {taskinstance.py:1373} INFO - Marking task as UP_FOR_RETRY. dag_id=dag_maestro, task_id=load_csv_to_mysql, execution_date=20250309T235629, start_date=20250310T000515, end_date=20250310T000517
[2025-03-10T00:05:17.937+0000] {standard_task_runner.py:109} ERROR - Failed to execute job 18 for task load_csv_to_mysql (Dag id crear_tabla_mysql not found; 678)
[2025-03-10T00:05:17.995+0000] {local_task_job_runner.py:232} INFO - Task exited with return code 1
[2025-03-10T00:05:18.220+0000] {taskinstance.py:2674} INFO - 0 downstream tasks scheduled from follow-on schedule check
