[2025-05-03T19:29:19.341+0000] {local_task_job_runner.py:120} INFO - ::group::Pre task execution logs
[2025-05-03T19:29:19.588+0000] {taskinstance.py:2073} INFO - Dependencies all met for dep_context=non-requeueable deps ti=<TaskInstance: diabetes_model_pipeline.process_train_and_build_model manual__2025-05-03T19:29:06.889512+00:00 [queued]>
[2025-05-03T19:29:19.606+0000] {taskinstance.py:2073} INFO - Dependencies all met for dep_context=requeueable deps ti=<TaskInstance: diabetes_model_pipeline.process_train_and_build_model manual__2025-05-03T19:29:06.889512+00:00 [queued]>
[2025-05-03T19:29:19.606+0000] {taskinstance.py:2303} INFO - Starting attempt 1 of 2
[2025-05-03T19:29:19.679+0000] {taskinstance.py:2327} INFO - Executing <Task(PythonOperator): process_train_and_build_model> on 2025-05-03 19:29:06.889512+00:00
[2025-05-03T19:29:19.780+0000] {standard_task_runner.py:63} INFO - Started process 11855 to run task
[2025-05-03T19:29:19.791+0000] {standard_task_runner.py:90} INFO - Running: ['***', 'tasks', 'run', 'diabetes_model_pipeline', 'process_train_and_build_model', 'manual__2025-05-03T19:29:06.889512+00:00', '--job-id', '368', '--raw', '--subdir', 'DAGS_FOLDER/model.py', '--cfg-path', '/tmp/tmpsh1th158']
[2025-05-03T19:29:19.826+0000] {standard_task_runner.py:91} INFO - Job 368: Subtask process_train_and_build_model
[2025-05-03T19:29:20.374+0000] {task_command.py:426} INFO - Running <TaskInstance: diabetes_model_pipeline.process_train_and_build_model manual__2025-05-03T19:29:06.889512+00:00 [running]> on host 31e5ce530290
[2025-05-03T19:29:21.170+0000] {taskinstance.py:2644} INFO - Exporting env vars: AIRFLOW_CTX_DAG_OWNER='***' AIRFLOW_CTX_DAG_ID='diabetes_model_pipeline' AIRFLOW_CTX_TASK_ID='process_train_and_build_model' AIRFLOW_CTX_EXECUTION_DATE='2025-05-03T19:29:06.889512+00:00' AIRFLOW_CTX_TRY_NUMBER='1' AIRFLOW_CTX_DAG_RUN_ID='manual__2025-05-03T19:29:06.889512+00:00'
[2025-05-03T19:29:21.177+0000] {taskinstance.py:430} INFO - ::endgroup::
[2025-05-03T19:29:21.289+0000] {crypto.py:82} WARNING - empty cryptography key - values will not be stored encrypted.
[2025-05-03T19:29:21.290+0000] {base.py:84} INFO - Using connection ID 'mysql_diabetes_conn' for task execution.
[2025-05-03T19:29:21.464+0000] {warnings.py:109} WARNING - /home/***/.local/lib/python3.8/site-packages/***/providers/common/sql/hooks/sql.py:227: UserWarning: pandas only supports SQLAlchemy connectable (engine/connection) or database string URI or sqlite3 DBAPI2 connection. Other DBAPI2 objects are not tested. Please consider using SQLAlchemy.
  return psql.read_sql(sql, con=conn, params=parameters, **kwargs)

[2025-05-03T19:29:44.332+0000] {logging_mixin.py:188} INFO - Datos de entrenamiento:
[2025-05-03T19:29:44.338+0000] {logging_mixin.py:188} INFO - - Forma: (61059, 87)
[2025-05-03T19:29:44.343+0000] {logging_mixin.py:188} INFO - - Columnas: ['feature_0', 'feature_1', 'feature_2', 'feature_3', 'feature_4', 'feature_5', 'feature_6', 'feature_7', 'feature_8', 'feature_9', 'feature_10', 'feature_11', 'feature_12', 'feature_13', 'feature_14', 'feature_15', 'feature_16', 'feature_17', 'feature_18', 'feature_19', 'feature_20', 'feature_21', 'feature_22', 'feature_23', 'feature_24', 'feature_25', 'feature_26', 'feature_27', 'feature_28', 'feature_29', 'feature_30', 'feature_31', 'feature_32', 'feature_33', 'feature_34', 'feature_35', 'feature_36', 'feature_37', 'feature_38', 'feature_39', 'feature_40', 'feature_41', 'feature_42', 'feature_43', 'feature_44', 'feature_45', 'feature_46', 'feature_47', 'feature_48', 'feature_49', 'feature_50', 'feature_51', 'feature_52', 'feature_53', 'feature_54', 'feature_55', 'feature_56', 'feature_57', 'feature_58', 'feature_59', 'feature_60', 'feature_61', 'feature_62', 'feature_63', 'feature_64', 'feature_65', 'feature_66', 'feature_67', 'feature_68', 'feature_69', 'feature_70', 'feature_71', 'feature_72', 'feature_73', 'feature_74', 'feature_75', 'feature_76', 'feature_77', 'feature_78', 'feature_79', 'feature_80', 'feature_81', 'feature_82', 'feature_83', 'feature_84', 'feature_85', 'target']
[2025-05-03T19:29:44.433+0000] {logging_mixin.py:188} INFO - Distribuci�n original de clases (entrenamiento):
[2025-05-03T19:29:44.521+0000] {logging_mixin.py:188} INFO - target
NO     32918
YES    28141
Name: count, dtype: int64
[2025-05-03T19:29:47.741+0000] {logging_mixin.py:188} INFO - Aplicando undersampling al conjunto de entrenamiento...
[2025-05-03T19:29:48.088+0000] {logging_mixin.py:188} INFO - Class distribution before undersampling:
[2025-05-03T19:29:48.089+0000] {logging_mixin.py:188} INFO -   Class NO: 32918 samples
[2025-05-03T19:29:48.089+0000] {logging_mixin.py:188} INFO -   Class YES: 28141 samples
[2025-05-03T19:29:48.779+0000] {logging_mixin.py:188} INFO - Class distribution after undersampling:
[2025-05-03T19:29:48.781+0000] {logging_mixin.py:188} INFO -   Class NO: 28141 samples
[2025-05-03T19:29:48.781+0000] {logging_mixin.py:188} INFO -   Class YES: 28141 samples
[2025-05-03T19:29:48.782+0000] {logging_mixin.py:188} INFO - Forma despu�s de undersampling: X((56282, 86)), y(56282)
[2025-05-03T19:29:48.782+0000] {logging_mixin.py:188} INFO - Entrenando modelo con datos balanceados...
[2025-05-03T19:38:37.090+0000] {job.py:218} ERROR - Job heartbeat got an exception
Traceback (most recent call last):
  File "/home/airflow/.local/lib/python3.8/site-packages/sqlalchemy/engine/base.py", line 3371, in _wrap_pool_connect
    return fn()
  File "/home/airflow/.local/lib/python3.8/site-packages/sqlalchemy/pool/base.py", line 327, in connect
    return _ConnectionFairy._checkout(self)
  File "/home/airflow/.local/lib/python3.8/site-packages/sqlalchemy/pool/base.py", line 894, in _checkout
    fairy = _ConnectionRecord.checkout(pool)
  File "/home/airflow/.local/lib/python3.8/site-packages/sqlalchemy/pool/base.py", line 493, in checkout
    rec = pool._do_get()
  File "/home/airflow/.local/lib/python3.8/site-packages/sqlalchemy/pool/impl.py", line 256, in _do_get
    return self._create_connection()
  File "/home/airflow/.local/lib/python3.8/site-packages/sqlalchemy/pool/base.py", line 273, in _create_connection
    return _ConnectionRecord(self)
  File "/home/airflow/.local/lib/python3.8/site-packages/sqlalchemy/pool/base.py", line 388, in __init__
    self.__connect()
  File "/home/airflow/.local/lib/python3.8/site-packages/sqlalchemy/pool/base.py", line 691, in __connect
    pool.logger.debug("Error on connect(): %s", e)
  File "/home/airflow/.local/lib/python3.8/site-packages/sqlalchemy/util/langhelpers.py", line 70, in __exit__
    compat.raise_(
  File "/home/airflow/.local/lib/python3.8/site-packages/sqlalchemy/util/compat.py", line 211, in raise_
    raise exception
  File "/home/airflow/.local/lib/python3.8/site-packages/sqlalchemy/pool/base.py", line 686, in __connect
    self.dbapi_connection = connection = pool._invoke_creator(self)
  File "/home/airflow/.local/lib/python3.8/site-packages/sqlalchemy/engine/create.py", line 574, in connect
    return dialect.connect(*cargs, **cparams)
  File "/home/airflow/.local/lib/python3.8/site-packages/sqlalchemy/engine/default.py", line 598, in connect
    return self.dbapi.connect(*cargs, **cparams)
  File "/home/airflow/.local/lib/python3.8/site-packages/MySQLdb/__init__.py", line 121, in Connect
    return Connection(*args, **kwargs)
  File "/home/airflow/.local/lib/python3.8/site-packages/MySQLdb/connections.py", line 195, in __init__
    super().__init__(*args, **kwargs2)
MySQLdb.OperationalError: (2005, "Unknown server host 'mysql' (-3)")

The above exception was the direct cause of the following exception:

Traceback (most recent call last):
  File "/home/airflow/.local/lib/python3.8/site-packages/airflow/jobs/job.py", line 192, in heartbeat
    self._merge_from(Job._fetch_from_db(self, session))
  File "/home/airflow/.local/lib/python3.8/site-packages/airflow/api_internal/internal_api_call.py", line 115, in wrapper
    return func(*args, **kwargs)
  File "/home/airflow/.local/lib/python3.8/site-packages/airflow/utils/session.py", line 76, in wrapper
    return func(*args, **kwargs)
  File "/home/airflow/.local/lib/python3.8/site-packages/airflow/utils/retries.py", line 89, in wrapped_function
    for attempt in run_with_db_retries(max_retries=retries, logger=logger, **retry_kwargs):
  File "/home/airflow/.local/lib/python3.8/site-packages/tenacity/__init__.py", line 347, in __iter__
    do = self.iter(retry_state=retry_state)
  File "/home/airflow/.local/lib/python3.8/site-packages/tenacity/__init__.py", line 325, in iter
    raise retry_exc.reraise()
  File "/home/airflow/.local/lib/python3.8/site-packages/tenacity/__init__.py", line 158, in reraise
    raise self.last_attempt.result()
  File "/usr/local/lib/python3.8/concurrent/futures/_base.py", line 437, in result
    return self.__get_result()
  File "/usr/local/lib/python3.8/concurrent/futures/_base.py", line 389, in __get_result
    raise self._exception
  File "/home/airflow/.local/lib/python3.8/site-packages/airflow/utils/retries.py", line 98, in wrapped_function
    return func(*args, **kwargs)
  File "/home/airflow/.local/lib/python3.8/site-packages/airflow/jobs/job.py", line 316, in _fetch_from_db
    session.merge(job)
  File "/home/airflow/.local/lib/python3.8/site-packages/sqlalchemy/orm/session.py", line 3056, in merge
    return self._merge(
  File "/home/airflow/.local/lib/python3.8/site-packages/sqlalchemy/orm/session.py", line 3136, in _merge
    merged = self.get(
  File "/home/airflow/.local/lib/python3.8/site-packages/sqlalchemy/orm/session.py", line 2853, in get
    return self._get_impl(
  File "/home/airflow/.local/lib/python3.8/site-packages/sqlalchemy/orm/session.py", line 2975, in _get_impl
    return db_load_fn(
  File "/home/airflow/.local/lib/python3.8/site-packages/sqlalchemy/orm/loading.py", line 530, in load_on_pk_identity
    session.execute(
  File "/home/airflow/.local/lib/python3.8/site-packages/sqlalchemy/orm/session.py", line 1716, in execute
    conn = self._connection_for_bind(bind)
  File "/home/airflow/.local/lib/python3.8/site-packages/sqlalchemy/orm/session.py", line 1555, in _connection_for_bind
    return self._transaction._connection_for_bind(
  File "/home/airflow/.local/lib/python3.8/site-packages/sqlalchemy/orm/session.py", line 750, in _connection_for_bind
    conn = bind.connect()
  File "/home/airflow/.local/lib/python3.8/site-packages/sqlalchemy/future/engine.py", line 412, in connect
    return super(Engine, self).connect()
  File "/home/airflow/.local/lib/python3.8/site-packages/sqlalchemy/engine/base.py", line 3325, in connect
    return self._connection_cls(self, close_with_result=close_with_result)
  File "/home/airflow/.local/lib/python3.8/site-packages/sqlalchemy/engine/base.py", line 96, in __init__
    else engine.raw_connection()
  File "/home/airflow/.local/lib/python3.8/site-packages/sqlalchemy/engine/base.py", line 3404, in raw_connection
    return self._wrap_pool_connect(self.pool.connect, _connection)
  File "/home/airflow/.local/lib/python3.8/site-packages/sqlalchemy/engine/base.py", line 3374, in _wrap_pool_connect
    Connection._handle_dbapi_exception_noconnection(
  File "/home/airflow/.local/lib/python3.8/site-packages/sqlalchemy/engine/base.py", line 2208, in _handle_dbapi_exception_noconnection
    util.raise_(
  File "/home/airflow/.local/lib/python3.8/site-packages/sqlalchemy/util/compat.py", line 211, in raise_
    raise exception
  File "/home/airflow/.local/lib/python3.8/site-packages/sqlalchemy/engine/base.py", line 3371, in _wrap_pool_connect
    return fn()
  File "/home/airflow/.local/lib/python3.8/site-packages/sqlalchemy/pool/base.py", line 327, in connect
    return _ConnectionFairy._checkout(self)
  File "/home/airflow/.local/lib/python3.8/site-packages/sqlalchemy/pool/base.py", line 894, in _checkout
    fairy = _ConnectionRecord.checkout(pool)
  File "/home/airflow/.local/lib/python3.8/site-packages/sqlalchemy/pool/base.py", line 493, in checkout
    rec = pool._do_get()
  File "/home/airflow/.local/lib/python3.8/site-packages/sqlalchemy/pool/impl.py", line 256, in _do_get
    return self._create_connection()
  File "/home/airflow/.local/lib/python3.8/site-packages/sqlalchemy/pool/base.py", line 273, in _create_connection
    return _ConnectionRecord(self)
  File "/home/airflow/.local/lib/python3.8/site-packages/sqlalchemy/pool/base.py", line 388, in __init__
    self.__connect()
  File "/home/airflow/.local/lib/python3.8/site-packages/sqlalchemy/pool/base.py", line 691, in __connect
    pool.logger.debug("Error on connect(): %s", e)
  File "/home/airflow/.local/lib/python3.8/site-packages/sqlalchemy/util/langhelpers.py", line 70, in __exit__
    compat.raise_(
  File "/home/airflow/.local/lib/python3.8/site-packages/sqlalchemy/util/compat.py", line 211, in raise_
    raise exception
  File "/home/airflow/.local/lib/python3.8/site-packages/sqlalchemy/pool/base.py", line 686, in __connect
    self.dbapi_connection = connection = pool._invoke_creator(self)
  File "/home/airflow/.local/lib/python3.8/site-packages/sqlalchemy/engine/create.py", line 574, in connect
    return dialect.connect(*cargs, **cparams)
  File "/home/airflow/.local/lib/python3.8/site-packages/sqlalchemy/engine/default.py", line 598, in connect
    return self.dbapi.connect(*cargs, **cparams)
  File "/home/airflow/.local/lib/python3.8/site-packages/MySQLdb/__init__.py", line 121, in Connect
    return Connection(*args, **kwargs)
  File "/home/airflow/.local/lib/python3.8/site-packages/MySQLdb/connections.py", line 195, in __init__
    super().__init__(*args, **kwargs2)
sqlalchemy.exc.OperationalError: (MySQLdb.OperationalError) (2005, "Unknown server host 'mysql' (-3)")
(Background on this error at: https://sqlalche.me/e/14/e3q8)
[2025-05-03T19:38:38.277+0000] {job.py:226} ERROR - Job heartbeat failed with error. Scheduler is in unhealthy state
[2025-05-03T19:38:38.329+0000] {local_task_job_runner.py:214} ERROR - Heartbeat time limit exceeded!
[2025-05-03T19:38:38.329+0000] {local_task_job_runner.py:222} INFO - ::endgroup::
[2025-05-03T19:38:38.649+0000] {process_utils.py:132} INFO - Sending 15 to group 11855. PIDs of all processes in the group: [11855]
[2025-05-03T19:38:38.649+0000] {process_utils.py:87} INFO - Sending the signal 15 to group 11855
[2025-05-03T19:38:38.834+0000] {taskinstance.py:2607} ERROR - Received SIGTERM. Terminating subprocesses.
[2025-05-03T19:38:38.914+0000] {taskinstance.py:441} INFO - ::group::Post task execution logs
[2025-05-03T19:38:39.683+0000] {taskinstance.py:2890} ERROR - Task failed with exception
Traceback (most recent call last):
  File "/home/airflow/.local/lib/python3.8/site-packages/airflow/models/taskinstance.py", line 465, in _execute_task
    result = _execute_callable(context=context, **execute_callable_kwargs)
  File "/home/airflow/.local/lib/python3.8/site-packages/airflow/models/taskinstance.py", line 432, in _execute_callable
    return execute_callable(context=context, **execute_callable_kwargs)
  File "/home/airflow/.local/lib/python3.8/site-packages/airflow/models/baseoperator.py", line 400, in wrapper
    return func(self, *args, **kwargs)
  File "/home/airflow/.local/lib/python3.8/site-packages/airflow/operators/python.py", line 235, in execute
    return_value = self.execute_callable()
  File "/home/airflow/.local/lib/python3.8/site-packages/airflow/operators/python.py", line 252, in execute_callable
    return self.python_callable(*self.op_args, **self.op_kwargs)
  File "/opt/airflow/dags/model.py", line 295, in process_train_and_build_model
    trained_model, train_results = train_evaluate_transformed_data(
  File "/opt/airflow/dags/model.py", line 236, in train_evaluate_transformed_data
    y_pred = model.predict(X_test)
  File "/home/airflow/.local/lib/python3.8/site-packages/sklearn/ensemble/_forest.py", line 823, in predict
    proba = self.predict_proba(X)
  File "/home/airflow/.local/lib/python3.8/site-packages/sklearn/ensemble/_forest.py", line 876, in predict_proba
    Parallel(n_jobs=n_jobs, verbose=self.verbose, require="sharedmem")(
  File "/home/airflow/.local/lib/python3.8/site-packages/sklearn/utils/parallel.py", line 65, in __call__
    return super().__call__(iterable_with_config)
  File "/home/airflow/.local/lib/python3.8/site-packages/joblib/parallel.py", line 1918, in __call__
    return output if self.return_generator else list(output)
  File "/home/airflow/.local/lib/python3.8/site-packages/joblib/parallel.py", line 1847, in _get_sequential_output
    res = func(*args, **kwargs)
  File "/home/airflow/.local/lib/python3.8/site-packages/sklearn/utils/parallel.py", line 127, in __call__
    return self.function(*args, **kwargs)
  File "/home/airflow/.local/lib/python3.8/site-packages/sklearn/ensemble/_forest.py", line 647, in _accumulate_prediction
    prediction = predict(X, check_input=False)
  File "/home/airflow/.local/lib/python3.8/site-packages/sklearn/tree/_classes.py", line 993, in predict_proba
    proba = self.tree_.predict(X)
  File "/home/airflow/.local/lib/python3.8/site-packages/airflow/models/taskinstance.py", line 2609, in signal_handler
    raise AirflowTaskTerminated("Task received SIGTERM signal")
airflow.exceptions.AirflowTaskTerminated: Task received SIGTERM signal
[2025-05-03T19:38:40.439+0000] {taskinstance.py:1205} INFO - Marking task as UP_FOR_RETRY. dag_id=diabetes_model_pipeline, task_id=process_train_and_build_model, execution_date=20250503T192906, start_date=20250503T192919, end_date=20250503T193840
[2025-05-03T19:38:43.194+0000] {process_utils.py:80} INFO - Process psutil.Process(pid=11855, status='terminated', exitcode=2, started='19:29:19') (11855) terminated with exit code 2
