[2025-05-05T01:00:17.529+0000] {scheduler_job_runner.py:769} ERROR - Executor reports task instance <TaskInstance: diabetes_etl_fast.process_save_test_data manual__2025-05-05T00:52:43.453118+00:00 [queued]> finished (failed) although the task says it's queued. (Info: None) Was the task killed externally?
