[2025-03-31T00:56:37.752+0000] {taskinstance.py:1125} INFO - Dependencies all met for dep_context=non-requeueable deps ti=<TaskInstance: train_model.train_model manual__2025-03-31T00:56:34.208127+00:00 [queued]>
[2025-03-31T00:56:37.765+0000] {taskinstance.py:1125} INFO - Dependencies all met for dep_context=requeueable deps ti=<TaskInstance: train_model.train_model manual__2025-03-31T00:56:34.208127+00:00 [queued]>
[2025-03-31T00:56:37.765+0000] {taskinstance.py:1331} INFO - Starting attempt 1 of 2
[2025-03-31T00:56:37.788+0000] {taskinstance.py:1350} INFO - Executing <Task(PythonOperator): train_model> on 2025-03-31 00:56:34.208127+00:00
[2025-03-31T00:56:37.806+0000] {standard_task_runner.py:57} INFO - Started process 1180 to run task
[2025-03-31T00:56:37.814+0000] {standard_task_runner.py:84} INFO - Running: ['***', 'tasks', 'run', 'train_model', 'train_model', 'manual__2025-03-31T00:56:34.208127+00:00', '--job-id', '542', '--raw', '--subdir', 'DAGS_FOLDER/train.py', '--cfg-path', '/tmp/tmpidz046ta']
[2025-03-31T00:56:37.818+0000] {standard_task_runner.py:85} INFO - Job 542: Subtask train_model
[2025-03-31T00:56:37.911+0000] {task_command.py:410} INFO - Running <TaskInstance: train_model.train_model manual__2025-03-31T00:56:34.208127+00:00 [running]> on host 76e1807f7118
[2025-03-31T00:56:38.045+0000] {taskinstance.py:1570} INFO - Exporting env vars: AIRFLOW_CTX_DAG_OWNER='***' AIRFLOW_CTX_DAG_ID='train_model' AIRFLOW_CTX_TASK_ID='train_model' AIRFLOW_CTX_EXECUTION_DATE='2025-03-31T00:56:34.208127+00:00' AIRFLOW_CTX_TRY_NUMBER='1' AIRFLOW_CTX_DAG_RUN_ID='manual__2025-03-31T00:56:34.208127+00:00'
[2025-03-31T00:56:38.062+0000] {base.py:73} INFO - Using connection ID 'mysql_***_conn' for task execution.
[2025-03-31T00:56:38.190+0000] {logging_mixin.py:149} INFO - Experiment 'mlflow_tracking_examples_3' already exists with ID: 1
[2025-03-31T00:56:38.191+0000] {taskinstance.py:1847} ERROR - Task failed with exception
Traceback (most recent call last):
  File "/home/airflow/.local/lib/python3.7/site-packages/airflow/operators/python.py", line 181, in execute
    return_value = self.execute_callable()
  File "/home/airflow/.local/lib/python3.7/site-packages/airflow/operators/python.py", line 198, in execute_callable
    return self.python_callable(*self.op_args, **self.op_kwargs)
  File "/opt/airflow/dags/train.py", line 81, in train_model
    with mlflow.start_run(run_name="svm_artifacts") as run:
  File "/home/airflow/.local/lib/python3.7/site-packages/mlflow/tracking/fluent.py", line 279, in start_run
    client = MlflowClient()
  File "/home/airflow/.local/lib/python3.7/site-packages/mlflow/tracking/client.py", line 66, in __init__
    self._tracking_client = TrackingServiceClient(final_tracking_uri)
  File "/home/airflow/.local/lib/python3.7/site-packages/mlflow/tracking/_tracking_service/client.py", line 51, in __init__
    self.store
  File "/home/airflow/.local/lib/python3.7/site-packages/mlflow/tracking/_tracking_service/client.py", line 55, in store
    return utils._get_store(self.tracking_uri)
  File "/home/airflow/.local/lib/python3.7/site-packages/mlflow/tracking/_tracking_service/utils.py", line 188, in _get_store
    return _tracking_store_registry.get_store(store_uri, artifact_uri)
  File "/home/airflow/.local/lib/python3.7/site-packages/mlflow/tracking/_tracking_service/registry.py", line 39, in get_store
    return self._get_store_with_resolved_uri(resolved_store_uri, artifact_uri)
  File "/home/airflow/.local/lib/python3.7/site-packages/mlflow/tracking/_tracking_service/registry.py", line 49, in _get_store_with_resolved_uri
    return builder(store_uri=resolved_store_uri, artifact_uri=artifact_uri)
  File "/home/airflow/.local/lib/python3.7/site-packages/mlflow/tracking/_tracking_service/utils.py", line 141, in _get_file_store
    return FileStore(store_uri, store_uri)
  File "/home/airflow/.local/lib/python3.7/site-packages/mlflow/store/tracking/file_store.py", line 153, in __init__
    mkdir(self.root_directory)
  File "/home/airflow/.local/lib/python3.7/site-packages/mlflow/utils/file_utils.py", line 121, in mkdir
    raise e
  File "/home/airflow/.local/lib/python3.7/site-packages/mlflow/utils/file_utils.py", line 118, in mkdir
    os.makedirs(target)
  File "/usr/local/lib/python3.7/os.py", line 223, in makedirs
    mkdir(name, mode)
PermissionError: [Errno 13] Permission denied: '/src/mlruns'
[2025-03-31T00:56:38.209+0000] {taskinstance.py:1373} INFO - Marking task as UP_FOR_RETRY. dag_id=train_model, task_id=train_model, execution_date=20250331T005634, start_date=20250331T005637, end_date=20250331T005638
[2025-03-31T00:56:38.230+0000] {standard_task_runner.py:109} ERROR - Failed to execute job 542 for task train_model ([Errno 13] Permission denied: '/src/mlruns'; 1180)
[2025-03-31T00:56:38.266+0000] {local_task_job_runner.py:232} INFO - Task exited with return code 1
[2025-03-31T00:56:38.303+0000] {taskinstance.py:2674} INFO - 0 downstream tasks scheduled from follow-on schedule check
