[2025-03-09T14:01:33.519+0000] {taskinstance.py:1125} INFO - Dependencies all met for dep_context=non-requeueable deps ti=<TaskInstance: crear_tabla_mysql.load_csv_to_mysql manual__2025-03-09T13:56:25.207212+00:00 [queued]>
[2025-03-09T14:01:33.595+0000] {taskinstance.py:1125} INFO - Dependencies all met for dep_context=requeueable deps ti=<TaskInstance: crear_tabla_mysql.load_csv_to_mysql manual__2025-03-09T13:56:25.207212+00:00 [queued]>
[2025-03-09T14:01:33.596+0000] {taskinstance.py:1331} INFO - Starting attempt 2 of 2
[2025-03-09T14:01:33.681+0000] {taskinstance.py:1350} INFO - Executing <Task(PythonOperator): load_csv_to_mysql> on 2025-03-09 13:56:25.207212+00:00
[2025-03-09T14:01:33.697+0000] {standard_task_runner.py:57} INFO - Started process 183 to run task
[2025-03-09T14:01:33.715+0000] {standard_task_runner.py:84} INFO - Running: ['***', 'tasks', 'run', 'crear_tabla_mysql', 'load_csv_to_mysql', 'manual__2025-03-09T13:56:25.207212+00:00', '--job-id', '9', '--raw', '--subdir', 'DAGS_FOLDER/mysql_create_table.py', '--cfg-path', '/tmp/tmpnjaw0blp']
[2025-03-09T14:01:33.724+0000] {standard_task_runner.py:85} INFO - Job 9: Subtask load_csv_to_mysql
[2025-03-09T14:01:33.880+0000] {task_command.py:410} INFO - Running <TaskInstance: crear_tabla_mysql.load_csv_to_mysql manual__2025-03-09T13:56:25.207212+00:00 [running]> on host fbbe010f2ede
[2025-03-09T14:01:34.214+0000] {taskinstance.py:1570} INFO - Exporting env vars: AIRFLOW_CTX_DAG_OWNER='***' AIRFLOW_CTX_DAG_ID='crear_tabla_mysql' AIRFLOW_CTX_TASK_ID='load_csv_to_mysql' AIRFLOW_CTX_EXECUTION_DATE='2025-03-09T13:56:25.207212+00:00' AIRFLOW_CTX_TRY_NUMBER='2' AIRFLOW_CTX_DAG_RUN_ID='manual__2025-03-09T13:56:25.207212+00:00'
[2025-03-09T14:01:34.312+0000] {taskinstance.py:1847} ERROR - Task failed with exception
Traceback (most recent call last):
  File "/home/airflow/.local/lib/python3.7/site-packages/airflow/operators/python.py", line 181, in execute
    return_value = self.execute_callable()
  File "/home/airflow/.local/lib/python3.7/site-packages/airflow/operators/python.py", line 198, in execute_callable
    return self.python_callable(*self.op_args, **self.op_kwargs)
  File "/opt/airflow/dags/mysql_create_table.py", line 14, in load_csv_to_mysql
    engine = mysql_hook.get_sqlalchemy_engine()
  File "/home/airflow/.local/lib/python3.7/site-packages/airflow/providers/common/sql/hooks/sql.py", line 181, in get_sqlalchemy_engine
    return create_engine(self.get_uri(), **engine_kwargs)
  File "/home/airflow/.local/lib/python3.7/site-packages/airflow/providers/common/sql/hooks/sql.py", line 168, in get_uri
    conn = self.get_connection(getattr(self, self.conn_name_attr))
  File "/home/airflow/.local/lib/python3.7/site-packages/airflow/hooks/base.py", line 72, in get_connection
    conn = Connection.get_connection_from_secrets(conn_id)
  File "/home/airflow/.local/lib/python3.7/site-packages/airflow/models/connection.py", line 434, in get_connection_from_secrets
    raise AirflowNotFoundException(f"The conn_id `{conn_id}` isn't defined")
airflow.exceptions.AirflowNotFoundException: The conn_id `mysql_***_conn` isn't defined
[2025-03-09T14:01:34.327+0000] {taskinstance.py:1373} INFO - Marking task as FAILED. dag_id=crear_tabla_mysql, task_id=load_csv_to_mysql, execution_date=20250309T135625, start_date=20250309T140133, end_date=20250309T140134
[2025-03-09T14:01:34.376+0000] {standard_task_runner.py:109} ERROR - Failed to execute job 9 for task load_csv_to_mysql (The conn_id `mysql_***_conn` isn't defined; 183)
[2025-03-09T14:01:34.415+0000] {local_task_job_runner.py:232} INFO - Task exited with return code 1
[2025-03-09T14:01:34.490+0000] {taskinstance.py:2674} INFO - 0 downstream tasks scheduled from follow-on schedule check
