[2025-03-10T00:52:58.766+0000] {taskinstance.py:1125} INFO - Dependencies all met for dep_context=non-requeueable deps ti=<TaskInstance: dag_maestro.load_data manual__2025-03-10T00:51:53.389753+00:00 [queued]>
[2025-03-10T00:52:58.782+0000] {taskinstance.py:1125} INFO - Dependencies all met for dep_context=requeueable deps ti=<TaskInstance: dag_maestro.load_data manual__2025-03-10T00:51:53.389753+00:00 [queued]>
[2025-03-10T00:52:58.782+0000] {taskinstance.py:1331} INFO - Starting attempt 1 of 2
[2025-03-10T00:52:58.805+0000] {taskinstance.py:1350} INFO - Executing <Task(TriggerDagRunOperator): load_data> on 2025-03-10 00:51:53.389753+00:00
[2025-03-10T00:52:58.823+0000] {standard_task_runner.py:57} INFO - Started process 392 to run task
[2025-03-10T00:52:58.830+0000] {standard_task_runner.py:84} INFO - Running: ['***', 'tasks', 'run', 'dag_maestro', 'load_data', 'manual__2025-03-10T00:51:53.389753+00:00', '--job-id', '139', '--raw', '--subdir', 'DAGS_FOLDER/orchestrator.py', '--cfg-path', '/tmp/tmptfdcwwm_']
[2025-03-10T00:52:58.832+0000] {standard_task_runner.py:85} INFO - Job 139: Subtask load_data
[2025-03-10T00:52:58.984+0000] {task_command.py:410} INFO - Running <TaskInstance: dag_maestro.load_data manual__2025-03-10T00:51:53.389753+00:00 [running]> on host a7c8d6e00548
[2025-03-10T00:52:59.203+0000] {taskinstance.py:1570} INFO - Exporting env vars: AIRFLOW_CTX_DAG_OWNER='***' AIRFLOW_CTX_DAG_ID='dag_maestro' AIRFLOW_CTX_TASK_ID='load_data' AIRFLOW_CTX_EXECUTION_DATE='2025-03-10T00:51:53.389753+00:00' AIRFLOW_CTX_TRY_NUMBER='1' AIRFLOW_CTX_DAG_RUN_ID='manual__2025-03-10T00:51:53.389753+00:00'
[2025-03-10T00:52:59.347+0000] {trigger_dagrun.py:201} INFO - Waiting for load_data_mysql on 2025-03-10T00:52:59.204765+00:00 to become allowed state ['success'] ...
[2025-03-10T00:53:59.406+0000] {trigger_dagrun.py:201} INFO - Waiting for load_data_mysql on 2025-03-10T00:52:59.204765+00:00 to become allowed state ['success'] ...
[2025-03-10T00:54:59.503+0000] {trigger_dagrun.py:201} INFO - Waiting for load_data_mysql on 2025-03-10T00:52:59.204765+00:00 to become allowed state ['success'] ...
[2025-03-10T00:55:59.584+0000] {trigger_dagrun.py:201} INFO - Waiting for load_data_mysql on 2025-03-10T00:52:59.204765+00:00 to become allowed state ['success'] ...
[2025-03-10T00:56:59.660+0000] {trigger_dagrun.py:201} INFO - Waiting for load_data_mysql on 2025-03-10T00:52:59.204765+00:00 to become allowed state ['success'] ...
[2025-03-10T00:57:59.749+0000] {trigger_dagrun.py:201} INFO - Waiting for load_data_mysql on 2025-03-10T00:52:59.204765+00:00 to become allowed state ['success'] ...
[2025-03-10T00:58:59.851+0000] {taskinstance.py:1847} ERROR - Task failed with exception
Traceback (most recent call last):
  File "/home/airflow/.local/lib/python3.7/site-packages/airflow/operators/trigger_dagrun.py", line 208, in execute
    raise AirflowException(f"{self.trigger_dag_id} failed with failed states {state}")
airflow.exceptions.AirflowException: load_data_mysql failed with failed states failed
[2025-03-10T00:58:59.858+0000] {taskinstance.py:1373} INFO - Marking task as UP_FOR_RETRY. dag_id=dag_maestro, task_id=load_data, execution_date=20250310T005153, start_date=20250310T005258, end_date=20250310T005859
[2025-03-10T00:58:59.878+0000] {standard_task_runner.py:109} ERROR - Failed to execute job 139 for task load_data (load_data_mysql failed with failed states failed; 392)
[2025-03-10T00:58:59.910+0000] {local_task_job_runner.py:232} INFO - Task exited with return code 1
[2025-03-10T00:58:59.969+0000] {taskinstance.py:2674} INFO - 0 downstream tasks scheduled from follow-on schedule check
