[2025-05-04T22:56:02.453+0000] {local_task_job_runner.py:120} INFO - ::group::Pre task execution logs
[2025-05-04T22:56:02.589+0000] {taskinstance.py:2073} INFO - Dependencies all met for dep_context=non-requeueable deps ti=<TaskInstance: iniciar_tabla_mysql.start_table manual__2025-05-04T22:52:03.659821+00:00 [queued]>
[2025-05-04T22:56:02.631+0000] {taskinstance.py:2073} INFO - Dependencies all met for dep_context=requeueable deps ti=<TaskInstance: iniciar_tabla_mysql.start_table manual__2025-05-04T22:52:03.659821+00:00 [queued]>
[2025-05-04T22:56:02.632+0000] {taskinstance.py:2303} INFO - Starting attempt 3 of 4
[2025-05-04T22:56:02.709+0000] {taskinstance.py:2327} INFO - Executing <Task(PythonOperator): start_table> on 2025-05-04 22:52:03.659821+00:00
[2025-05-04T22:56:02.739+0000] {standard_task_runner.py:63} INFO - Started process 99 to run task
[2025-05-04T22:56:02.754+0000] {standard_task_runner.py:90} INFO - Running: ['***', 'tasks', 'run', 'iniciar_tabla_mysql', 'start_table', 'manual__2025-05-04T22:52:03.659821+00:00', '--job-id', '15', '--raw', '--subdir', 'DAGS_FOLDER/mysql_start_table.py', '--cfg-path', '/tmp/tmp18zfl7l8']
[2025-05-04T22:56:02.771+0000] {standard_task_runner.py:91} INFO - Job 15: Subtask start_table
[2025-05-04T22:56:03.175+0000] {task_command.py:426} INFO - Running <TaskInstance: iniciar_tabla_mysql.start_table manual__2025-05-04T22:52:03.659821+00:00 [running]> on host 94fd3058cd44
[2025-05-04T22:56:03.679+0000] {taskinstance.py:2644} INFO - Exporting env vars: AIRFLOW_CTX_DAG_OWNER='***' AIRFLOW_CTX_DAG_ID='iniciar_tabla_mysql' AIRFLOW_CTX_TASK_ID='start_table' AIRFLOW_CTX_EXECUTION_DATE='2025-05-04T22:52:03.659821+00:00' AIRFLOW_CTX_TRY_NUMBER='3' AIRFLOW_CTX_DAG_RUN_ID='manual__2025-05-04T22:52:03.659821+00:00'
[2025-05-04T22:56:03.682+0000] {taskinstance.py:430} INFO - ::endgroup::
[2025-05-04T22:56:03.777+0000] {base.py:84} INFO - Using connection ID 'mysql_***_conn' for task execution.
[2025-05-04T22:56:03.816+0000] {taskinstance.py:441} INFO - ::group::Post task execution logs
[2025-05-04T22:56:03.819+0000] {taskinstance.py:2890} ERROR - Task failed with exception
Traceback (most recent call last):
  File "/home/airflow/.local/lib/python3.8/site-packages/airflow/models/taskinstance.py", line 465, in _execute_task
    result = _execute_callable(context=context, **execute_callable_kwargs)
  File "/home/airflow/.local/lib/python3.8/site-packages/airflow/models/taskinstance.py", line 432, in _execute_callable
    return execute_callable(context=context, **execute_callable_kwargs)
  File "/home/airflow/.local/lib/python3.8/site-packages/airflow/models/baseoperator.py", line 400, in wrapper
    return func(self, *args, **kwargs)
  File "/home/airflow/.local/lib/python3.8/site-packages/airflow/operators/python.py", line 235, in execute
    return_value = self.execute_callable()
  File "/home/airflow/.local/lib/python3.8/site-packages/airflow/operators/python.py", line 252, in execute_callable
    return self.python_callable(*self.op_args, **self.op_kwargs)
  File "/opt/airflow/dags/mysql_start_table.py", line 74, in start_table
    with engine.begin() as connection:
  File "/home/airflow/.local/lib/python3.8/site-packages/sqlalchemy/engine/base.py", line 3153, in begin
    conn = self.connect(close_with_result=close_with_result)
  File "/home/airflow/.local/lib/python3.8/site-packages/sqlalchemy/engine/base.py", line 3325, in connect
    return self._connection_cls(self, close_with_result=close_with_result)
  File "/home/airflow/.local/lib/python3.8/site-packages/sqlalchemy/engine/base.py", line 96, in __init__
    else engine.raw_connection()
  File "/home/airflow/.local/lib/python3.8/site-packages/sqlalchemy/engine/base.py", line 3404, in raw_connection
    return self._wrap_pool_connect(self.pool.connect, _connection)
  File "/home/airflow/.local/lib/python3.8/site-packages/sqlalchemy/engine/base.py", line 3371, in _wrap_pool_connect
    return fn()
  File "/home/airflow/.local/lib/python3.8/site-packages/sqlalchemy/pool/base.py", line 327, in connect
    return _ConnectionFairy._checkout(self)
  File "/home/airflow/.local/lib/python3.8/site-packages/sqlalchemy/pool/base.py", line 894, in _checkout
    fairy = _ConnectionRecord.checkout(pool)
  File "/home/airflow/.local/lib/python3.8/site-packages/sqlalchemy/pool/base.py", line 493, in checkout
    rec = pool._do_get()
  File "/home/airflow/.local/lib/python3.8/site-packages/sqlalchemy/pool/impl.py", line 146, in _do_get
    self._dec_overflow()
  File "/home/airflow/.local/lib/python3.8/site-packages/sqlalchemy/util/langhelpers.py", line 70, in __exit__
    compat.raise_(
  File "/home/airflow/.local/lib/python3.8/site-packages/sqlalchemy/util/compat.py", line 211, in raise_
    raise exception
  File "/home/airflow/.local/lib/python3.8/site-packages/sqlalchemy/pool/impl.py", line 143, in _do_get
    return self._create_connection()
  File "/home/airflow/.local/lib/python3.8/site-packages/sqlalchemy/pool/base.py", line 273, in _create_connection
    return _ConnectionRecord(self)
  File "/home/airflow/.local/lib/python3.8/site-packages/sqlalchemy/pool/base.py", line 388, in __init__
    self.__connect()
  File "/home/airflow/.local/lib/python3.8/site-packages/sqlalchemy/pool/base.py", line 691, in __connect
    pool.logger.debug("Error on connect(): %s", e)
  File "/home/airflow/.local/lib/python3.8/site-packages/sqlalchemy/util/langhelpers.py", line 70, in __exit__
    compat.raise_(
  File "/home/airflow/.local/lib/python3.8/site-packages/sqlalchemy/util/compat.py", line 211, in raise_
    raise exception
  File "/home/airflow/.local/lib/python3.8/site-packages/sqlalchemy/pool/base.py", line 686, in __connect
    self.dbapi_connection = connection = pool._invoke_creator(self)
  File "/home/airflow/.local/lib/python3.8/site-packages/sqlalchemy/engine/create.py", line 574, in connect
    return dialect.connect(*cargs, **cparams)
  File "/home/airflow/.local/lib/python3.8/site-packages/sqlalchemy/engine/default.py", line 598, in connect
    return self.dbapi.connect(*cargs, **cparams)
  File "/home/airflow/.local/lib/python3.8/site-packages/MySQLdb/__init__.py", line 121, in Connect
    return Connection(*args, **kwargs)
  File "/home/airflow/.local/lib/python3.8/site-packages/MySQLdb/connections.py", line 195, in __init__
    super().__init__(*args, **kwargs2)
TypeError: '__extra__' is an invalid keyword argument for connect()
[2025-05-04T22:56:03.867+0000] {taskinstance.py:1205} INFO - Marking task as UP_FOR_RETRY. dag_id=iniciar_tabla_mysql, task_id=start_table, execution_date=20250504T225203, start_date=20250504T225602, end_date=20250504T225603
[2025-05-04T22:56:03.908+0000] {standard_task_runner.py:110} ERROR - Failed to execute job 15 for task start_table ('__extra__' is an invalid keyword argument for connect(); 99)
[2025-05-04T22:56:03.958+0000] {local_task_job_runner.py:240} INFO - Task exited with return code 1
[2025-05-04T22:56:04.017+0000] {taskinstance.py:3482} INFO - 0 downstream tasks scheduled from follow-on schedule check
[2025-05-04T22:56:04.024+0000] {local_task_job_runner.py:222} INFO - ::endgroup::
