[2025-03-30T22:24:06.105+0000] {taskinstance.py:1125} INFO - Dependencies all met for dep_context=non-requeueable deps ti=<TaskInstance: clean_transform_data.transform_data manual__2025-03-30T22:24:01.142267+00:00 [queued]>
[2025-03-30T22:24:06.121+0000] {taskinstance.py:1125} INFO - Dependencies all met for dep_context=requeueable deps ti=<TaskInstance: clean_transform_data.transform_data manual__2025-03-30T22:24:01.142267+00:00 [queued]>
[2025-03-30T22:24:06.121+0000] {taskinstance.py:1331} INFO - Starting attempt 1 of 2
[2025-03-30T22:24:06.144+0000] {taskinstance.py:1350} INFO - Executing <Task(PythonOperator): transform_data> on 2025-03-30 22:24:01.142267+00:00
[2025-03-30T22:24:06.165+0000] {standard_task_runner.py:57} INFO - Started process 1009 to run task
[2025-03-30T22:24:06.187+0000] {standard_task_runner.py:84} INFO - Running: ['***', 'tasks', 'run', 'clean_transform_data', 'transform_data', 'manual__2025-03-30T22:24:01.142267+00:00', '--job-id', '465', '--raw', '--subdir', 'DAGS_FOLDER/preprocess_data.py', '--cfg-path', '/tmp/tmp0za70fyi']
[2025-03-30T22:24:06.191+0000] {standard_task_runner.py:85} INFO - Job 465: Subtask transform_data
[2025-03-30T22:24:06.344+0000] {task_command.py:410} INFO - Running <TaskInstance: clean_transform_data.transform_data manual__2025-03-30T22:24:01.142267+00:00 [running]> on host 4c428920f0ab
[2025-03-30T22:24:06.572+0000] {taskinstance.py:1570} INFO - Exporting env vars: AIRFLOW_CTX_DAG_OWNER='***' AIRFLOW_CTX_DAG_ID='clean_transform_data' AIRFLOW_CTX_TASK_ID='transform_data' AIRFLOW_CTX_EXECUTION_DATE='2025-03-30T22:24:01.142267+00:00' AIRFLOW_CTX_TRY_NUMBER='1' AIRFLOW_CTX_DAG_RUN_ID='manual__2025-03-30T22:24:01.142267+00:00'
[2025-03-30T22:24:06.600+0000] {base.py:73} INFO - Using connection ID 'mysql_***_conn' for task execution.
[2025-03-30T22:24:06.630+0000] {base.py:73} INFO - Using connection ID 'mysql_***_conn' for task execution.
[2025-03-30T22:24:06.648+0000] {taskinstance.py:1847} ERROR - Task failed with exception
Traceback (most recent call last):
  File "/home/airflow/.local/lib/python3.7/site-packages/pandas/io/sql.py", line 2056, in execute
    cur.execute(*args, **kwargs)
  File "/home/airflow/.local/lib/python3.7/site-packages/MySQLdb/cursors.py", line 206, in execute
    res = self._query(query)
  File "/home/airflow/.local/lib/python3.7/site-packages/MySQLdb/cursors.py", line 319, in _query
    db.query(q)
  File "/home/airflow/.local/lib/python3.7/site-packages/MySQLdb/connections.py", line 254, in query
    _mysql.connection.query(self, query)
MySQLdb.ProgrammingError: (1146, "Table '***.penguins_api' doesn't exist")

The above exception was the direct cause of the following exception:

Traceback (most recent call last):
  File "/home/airflow/.local/lib/python3.7/site-packages/airflow/operators/python.py", line 181, in execute
    return_value = self.execute_callable()
  File "/home/airflow/.local/lib/python3.7/site-packages/airflow/operators/python.py", line 198, in execute_callable
    return self.python_callable(*self.op_args, **self.op_kwargs)
  File "/opt/airflow/dags/preprocess_data.py", line 21, in clean_transform_data
    df = mysql_hook.get_pandas_df(sql_query) # Cargar datos guardados
  File "/home/airflow/.local/lib/python3.7/site-packages/airflow/providers/common/sql/hooks/sql.py", line 201, in get_pandas_df
    return psql.read_sql(sql, con=conn, params=parameters, **kwargs)
  File "/home/airflow/.local/lib/python3.7/site-packages/pandas/io/sql.py", line 608, in read_sql
    chunksize=chunksize,
  File "/home/airflow/.local/lib/python3.7/site-packages/pandas/io/sql.py", line 2116, in read_query
    cursor = self.execute(*args)
  File "/home/airflow/.local/lib/python3.7/site-packages/pandas/io/sql.py", line 2068, in execute
    raise ex from exc
pandas.io.sql.DatabaseError: Execution failed on sql 'SELECT * FROM penguins_api;': (1146, "Table '***.penguins_api' doesn't exist")
[2025-03-30T22:24:06.691+0000] {taskinstance.py:1373} INFO - Marking task as UP_FOR_RETRY. dag_id=clean_transform_data, task_id=transform_data, execution_date=20250330T222401, start_date=20250330T222406, end_date=20250330T222406
[2025-03-30T22:24:06.744+0000] {standard_task_runner.py:109} ERROR - Failed to execute job 465 for task transform_data (Execution failed on sql 'SELECT * FROM penguins_api;': (1146, "Table '***.penguins_api' doesn't exist"); 1009)
[2025-03-30T22:24:06.792+0000] {local_task_job_runner.py:232} INFO - Task exited with return code 1
[2025-03-30T22:24:06.859+0000] {taskinstance.py:2674} INFO - 0 downstream tasks scheduled from follow-on schedule check
