[2025-04-01T04:06:19.000+0000] {local_task_job_runner.py:120} INFO - ::group::Pre task execution logs
[2025-04-01T04:06:19.045+0000] {taskinstance.py:2073} INFO - Dependencies all met for dep_context=non-requeueable deps ti=<TaskInstance: train_model.train_model manual__2025-04-01T04:06:13.385813+00:00 [queued]>
[2025-04-01T04:06:19.068+0000] {taskinstance.py:2073} INFO - Dependencies all met for dep_context=requeueable deps ti=<TaskInstance: train_model.train_model manual__2025-04-01T04:06:13.385813+00:00 [queued]>
[2025-04-01T04:06:19.069+0000] {taskinstance.py:2303} INFO - Starting attempt 1 of 2
[2025-04-01T04:06:19.096+0000] {taskinstance.py:2327} INFO - Executing <Task(PythonOperator): train_model> on 2025-04-01 04:06:13.385813+00:00
[2025-04-01T04:06:19.122+0000] {standard_task_runner.py:63} INFO - Started process 249 to run task
[2025-04-01T04:06:19.134+0000] {standard_task_runner.py:90} INFO - Running: ['***', 'tasks', 'run', 'train_model', 'train_model', 'manual__2025-04-01T04:06:13.385813+00:00', '--job-id', '595', '--raw', '--subdir', 'DAGS_FOLDER/train.py', '--cfg-path', '/tmp/tmpwg8bl7xk']
[2025-04-01T04:06:19.141+0000] {standard_task_runner.py:91} INFO - Job 595: Subtask train_model
[2025-04-01T04:06:19.255+0000] {task_command.py:426} INFO - Running <TaskInstance: train_model.train_model manual__2025-04-01T04:06:13.385813+00:00 [running]> on host d34402ef6e0d
[2025-04-01T04:06:19.419+0000] {taskinstance.py:2644} INFO - Exporting env vars: AIRFLOW_CTX_DAG_OWNER='***' AIRFLOW_CTX_DAG_ID='train_model' AIRFLOW_CTX_TASK_ID='train_model' AIRFLOW_CTX_EXECUTION_DATE='2025-04-01T04:06:13.385813+00:00' AIRFLOW_CTX_TRY_NUMBER='1' AIRFLOW_CTX_DAG_RUN_ID='manual__2025-04-01T04:06:13.385813+00:00'
[2025-04-01T04:06:19.420+0000] {taskinstance.py:430} INFO - ::endgroup::
[2025-04-01T04:06:19.445+0000] {logging_mixin.py:188} INFO - MLflow Version: 2.17.2
[2025-04-01T04:06:19.480+0000] {base.py:84} INFO - Using connection ID 'mysql_***_conn' for task execution.
[2025-04-01T04:06:19.502+0000] {warnings.py:109} WARNING - /home/***/.local/lib/python3.8/site-packages/***/providers/common/sql/hooks/sql.py:227: UserWarning: pandas only supports SQLAlchemy connectable (engine/connection) or database string URI or sqlite3 DBAPI2 connection. Other DBAPI2 objects are not tested. Please consider using SQLAlchemy.
  return psql.read_sql(sql, con=conn, params=parameters, **kwargs)

[2025-04-01T04:06:19.892+0000] {logging_mixin.py:188} WARNING - 2025/04/01 04:06:19 WARNING mlflow.utils.git_utils: Failed to import Git (the Git executable is probably not on your PATH), so Git SHA is not available. Error: Failed to initialize: Bad git executable.
The git executable must be specified in one of the following ways:
    - be included in your $PATH
    - be set via $GIT_PYTHON_GIT_EXECUTABLE
    - explicitly set via git.refresh(<full-path-to-git-executable>)

All git commands will error until this is rectified.

This initial message can be silenced or aggravated in the future by setting the
$GIT_PYTHON_REFRESH environment variable. Use one of the following values:
    - quiet|q|silence|s|silent|none|n|0: for no message or exception
    - warn|w|warning|log|l|1: for a warning message (logging level CRITICAL, displayed by default)
    - error|e|exception|raise|r|2: for a raised exception

Example:
    export GIT_PYTHON_REFRESH=quiet
[2025-04-01T04:06:19.980+0000] {warnings.py:109} WARNING - /home/***/.local/lib/python3.8/site-packages/joblib/parallel.py:1359: UserWarning: Loky-backed parallel loops cannot be called in a multiprocessing, setting n_jobs=1
  n_jobs = self._backend.configure(n_jobs=self.n_jobs, parallel=self,

[2025-04-01T04:06:26.449+0000] {logging_mixin.py:188} WARNING - 2025/04/01 04:06:26 WARNING mlflow.models.model: Model logged without a signature and input example. Please set `input_example` parameter when logging the model to auto infer the model signature.
[2025-04-01T04:06:26.527+0000] {credentials.py:1147} INFO - Found credentials in environment variables.
[2025-04-01T04:06:27.114+0000] {logging_mixin.py:188} WARNING - Registered model 'svm-model' already exists. Creating a new version of this model...
[2025-04-01T04:06:27.216+0000] {logging_mixin.py:188} WARNING - 2025/04/01 04:06:27 INFO mlflow.store.model_registry.abstract_store: Waiting up to 300 seconds for model version to finish creation. Model name: svm-model, version 2
[2025-04-01T04:06:27.216+0000] {logging_mixin.py:188} WARNING - Created version '2' of model 'svm-model'.
[2025-04-01T04:06:27.275+0000] {logging_mixin.py:188} WARNING - 2025/04/01 04:06:27 INFO mlflow.tracking._tracking_service.client: üèÉ View run svm_artifacts at: http://mlflow:5000/#/experiments/1/runs/2d3cf5df36c4487dba02046d796b7d6f.
[2025-04-01T04:06:27.276+0000] {logging_mixin.py:188} WARNING - 2025/04/01 04:06:27 INFO mlflow.tracking._tracking_service.client: üß™ View experiment at: http://mlflow:5000/#/experiments/1.
[2025-04-01T04:06:27.322+0000] {taskinstance.py:441} INFO - ::group::Post task execution logs
[2025-04-01T04:06:27.323+0000] {taskinstance.py:2890} ERROR - Task failed with exception
Traceback (most recent call last):
  File "/home/airflow/.local/lib/python3.8/site-packages/airflow/models/taskinstance.py", line 465, in _execute_task
    result = _execute_callable(context=context, **execute_callable_kwargs)
  File "/home/airflow/.local/lib/python3.8/site-packages/airflow/models/taskinstance.py", line 432, in _execute_callable
    return execute_callable(context=context, **execute_callable_kwargs)
  File "/home/airflow/.local/lib/python3.8/site-packages/airflow/models/baseoperator.py", line 400, in wrapper
    return func(self, *args, **kwargs)
  File "/home/airflow/.local/lib/python3.8/site-packages/airflow/operators/python.py", line 235, in execute
    return_value = self.execute_callable()
  File "/home/airflow/.local/lib/python3.8/site-packages/airflow/operators/python.py", line 252, in execute_callable
    return self.python_callable(*self.op_args, **self.op_kwargs)
  File "/opt/airflow/dags/train.py", line 95, in train_model
    registered_model = client.create_registered_model(model_name)
  File "/home/airflow/.local/lib/python3.8/site-packages/mlflow/tracking/client.py", line 3109, in create_registered_model
    return self._get_registry_client().create_registered_model(name, tags, description)
  File "/home/airflow/.local/lib/python3.8/site-packages/mlflow/tracking/_model_registry/client.py", line 64, in create_registered_model
    return self.store.create_registered_model(name, tags, description)
  File "/home/airflow/.local/lib/python3.8/site-packages/mlflow/store/model_registry/rest_store.py", line 82, in create_registered_model
    response_proto = self._call_endpoint(CreateRegisteredModel, req_body)
  File "/home/airflow/.local/lib/python3.8/site-packages/mlflow/store/model_registry/base_rest_store.py", line 44, in _call_endpoint
    return call_endpoint(
  File "/home/airflow/.local/lib/python3.8/site-packages/mlflow/utils/rest_utils.py", line 370, in call_endpoint
    response = verify_rest_response(response, endpoint)
  File "/home/airflow/.local/lib/python3.8/site-packages/mlflow/utils/rest_utils.py", line 240, in verify_rest_response
    raise RestException(json.loads(response.text))
mlflow.exceptions.RestException: RESOURCE_ALREADY_EXISTS: Registered Model (name=svm-model) already exists. Error: (pymysql.err.IntegrityError) (1062, "Duplicate entry 'svm-model' for key 'registered_models.PRIMARY'")
[SQL: INSERT INTO registered_models (name, creation_time, last_updated_time, description) VALUES (%(name)s, %(creation_time)s, %(last_updated_time)s, %(description)s)]
[parameters: {'name': 'svm-model', 'creation_time': 1743480387228, 'last_updated_time': 1743480387228, 'description': ''}]
(Background on this error at: https://sqlalche.me/e/20/gkpj)
[2025-04-01T04:06:27.341+0000] {taskinstance.py:1205} INFO - Marking task as UP_FOR_RETRY. dag_id=train_model, task_id=train_model, execution_date=20250401T040613, start_date=20250401T040619, end_date=20250401T040627
[2025-04-01T04:06:27.368+0000] {standard_task_runner.py:110} ERROR - Failed to execute job 595 for task train_model (RESOURCE_ALREADY_EXISTS: Registered Model (name=svm-model) already exists. Error: (pymysql.err.IntegrityError) (1062, "Duplicate entry 'svm-model' for key 'registered_models.PRIMARY'")
[SQL: INSERT INTO registered_models (name, creation_time, last_updated_time, description) VALUES (%(name)s, %(creation_time)s, %(last_updated_time)s, %(description)s)]
[parameters: {'name': 'svm-model', 'creation_time': 1743480387228, 'last_updated_time': 1743480387228, 'description': ''}]
(Background on this error at: https://sqlalche.me/e/20/gkpj); 249)
[2025-04-01T04:06:27.456+0000] {local_task_job_runner.py:240} INFO - Task exited with return code 1
[2025-04-01T04:06:27.480+0000] {taskinstance.py:3482} INFO - 0 downstream tasks scheduled from follow-on schedule check
[2025-04-01T04:06:27.481+0000] {local_task_job_runner.py:222} INFO - ::endgroup::
