[2025-03-28T00:44:06.052+0000] {taskinstance.py:1125} INFO - Dependencies all met for dep_context=non-requeueable deps ti=<TaskInstance: data_api.g_data_api manual__2025-03-28T00:44:02.533447+00:00 [queued]>
[2025-03-28T00:44:06.082+0000] {taskinstance.py:1125} INFO - Dependencies all met for dep_context=requeueable deps ti=<TaskInstance: data_api.g_data_api manual__2025-03-28T00:44:02.533447+00:00 [queued]>
[2025-03-28T00:44:06.082+0000] {taskinstance.py:1331} INFO - Starting attempt 1 of 2
[2025-03-28T00:44:06.123+0000] {taskinstance.py:1350} INFO - Executing <Task(PythonOperator): g_data_api> on 2025-03-28 00:44:02.533447+00:00
[2025-03-28T00:44:06.142+0000] {standard_task_runner.py:57} INFO - Started process 428 to run task
[2025-03-28T00:44:06.152+0000] {standard_task_runner.py:84} INFO - Running: ['***', 'tasks', 'run', 'data_api', 'g_data_api', 'manual__2025-03-28T00:44:02.533447+00:00', '--job-id', '213', '--raw', '--subdir', 'DAGS_FOLDER/get_data.py', '--cfg-path', '/tmp/tmpihhp5801']
[2025-03-28T00:44:06.155+0000] {standard_task_runner.py:85} INFO - Job 213: Subtask g_data_api
[2025-03-28T00:44:06.320+0000] {task_command.py:410} INFO - Running <TaskInstance: data_api.g_data_api manual__2025-03-28T00:44:02.533447+00:00 [running]> on host 45230564970b
[2025-03-28T00:44:06.573+0000] {taskinstance.py:1570} INFO - Exporting env vars: AIRFLOW_CTX_DAG_OWNER='***' AIRFLOW_CTX_DAG_ID='data_api' AIRFLOW_CTX_TASK_ID='g_data_api' AIRFLOW_CTX_EXECUTION_DATE='2025-03-28T00:44:02.533447+00:00' AIRFLOW_CTX_TRY_NUMBER='1' AIRFLOW_CTX_DAG_RUN_ID='manual__2025-03-28T00:44:02.533447+00:00'
[2025-03-28T00:44:06.596+0000] {base.py:73} INFO - Using connection ID 'mysql_***_conn' for task execution.
[2025-03-28T00:44:06.639+0000] {logging_mixin.py:149} INFO - ❌ Error en la API (batch 1): 400 Client Error: Bad Request for url: http://10.43.101.166:80/data?group_number=6
[2025-03-28T00:44:06.648+0000] {logging_mixin.py:149} INFO - ❌ Error en la API (batch 2): 400 Client Error: Bad Request for url: http://10.43.101.166:80/data?group_number=6
[2025-03-28T00:44:06.655+0000] {logging_mixin.py:149} INFO - ❌ Error en la API (batch 3): 400 Client Error: Bad Request for url: http://10.43.101.166:80/data?group_number=6
[2025-03-28T00:44:06.662+0000] {logging_mixin.py:149} INFO - ❌ Error en la API (batch 4): 400 Client Error: Bad Request for url: http://10.43.101.166:80/data?group_number=6
[2025-03-28T00:44:06.671+0000] {logging_mixin.py:149} INFO - ❌ Error en la API (batch 5): 400 Client Error: Bad Request for url: http://10.43.101.166:80/data?group_number=6
[2025-03-28T00:44:06.681+0000] {logging_mixin.py:149} INFO - ❌ Error en la API (batch 6): 400 Client Error: Bad Request for url: http://10.43.101.166:80/data?group_number=6
[2025-03-28T00:44:06.688+0000] {logging_mixin.py:149} INFO - ❌ Error en la API (batch 7): 400 Client Error: Bad Request for url: http://10.43.101.166:80/data?group_number=6
[2025-03-28T00:44:06.694+0000] {logging_mixin.py:149} INFO - ❌ Error en la API (batch 8): 400 Client Error: Bad Request for url: http://10.43.101.166:80/data?group_number=6
[2025-03-28T00:44:06.706+0000] {logging_mixin.py:149} INFO - ❌ Error en la API (batch 9): 400 Client Error: Bad Request for url: http://10.43.101.166:80/data?group_number=6
[2025-03-28T00:44:06.712+0000] {logging_mixin.py:149} INFO - ❌ Error en la API (batch 10): 400 Client Error: Bad Request for url: http://10.43.101.166:80/data?group_number=6
[2025-03-28T00:44:06.714+0000] {python.py:183} INFO - Done. Returned value was: None
[2025-03-28T00:44:06.736+0000] {taskinstance.py:1373} INFO - Marking task as SUCCESS. dag_id=data_api, task_id=g_data_api, execution_date=20250328T004402, start_date=20250328T004406, end_date=20250328T004406
[2025-03-28T00:44:06.810+0000] {local_task_job_runner.py:232} INFO - Task exited with return code 0
[2025-03-28T00:44:06.853+0000] {taskinstance.py:2674} INFO - 0 downstream tasks scheduled from follow-on schedule check
