[2025-03-10T00:05:18.936+0000] {taskinstance.py:1125} INFO - Dependencies all met for dep_context=non-requeueable deps ti=<TaskInstance: dag_maestro.load_csv_to_mysql manual__2025-03-10T00:02:32.496605+00:00 [queued]>
[2025-03-10T00:05:18.980+0000] {taskinstance.py:1125} INFO - Dependencies all met for dep_context=requeueable deps ti=<TaskInstance: dag_maestro.load_csv_to_mysql manual__2025-03-10T00:02:32.496605+00:00 [queued]>
[2025-03-10T00:05:18.980+0000] {taskinstance.py:1331} INFO - Starting attempt 1 of 2
[2025-03-10T00:05:19.048+0000] {taskinstance.py:1350} INFO - Executing <Task(TriggerDagRunOperator): load_csv_to_mysql> on 2025-03-10 00:02:32.496605+00:00
[2025-03-10T00:05:19.082+0000] {standard_task_runner.py:57} INFO - Started process 682 to run task
[2025-03-10T00:05:19.102+0000] {standard_task_runner.py:84} INFO - Running: ['***', 'tasks', 'run', 'dag_maestro', 'load_csv_to_mysql', 'manual__2025-03-10T00:02:32.496605+00:00', '--job-id', '20', '--raw', '--subdir', 'DAGS_FOLDER/orchestrator.py', '--cfg-path', '/tmp/tmpzw__dxf3']
[2025-03-10T00:05:19.103+0000] {standard_task_runner.py:85} INFO - Job 20: Subtask load_csv_to_mysql
[2025-03-10T00:05:19.351+0000] {task_command.py:410} INFO - Running <TaskInstance: dag_maestro.load_csv_to_mysql manual__2025-03-10T00:02:32.496605+00:00 [running]> on host d7c1c9924032
[2025-03-10T00:05:19.792+0000] {taskinstance.py:1570} INFO - Exporting env vars: AIRFLOW_CTX_DAG_OWNER='***' AIRFLOW_CTX_DAG_ID='dag_maestro' AIRFLOW_CTX_TASK_ID='load_csv_to_mysql' AIRFLOW_CTX_EXECUTION_DATE='2025-03-10T00:02:32.496605+00:00' AIRFLOW_CTX_TRY_NUMBER='1' AIRFLOW_CTX_DAG_RUN_ID='manual__2025-03-10T00:02:32.496605+00:00'
[2025-03-10T00:05:19.936+0000] {taskinstance.py:1847} ERROR - Task failed with exception
Traceback (most recent call last):
  File "/home/airflow/.local/lib/python3.7/site-packages/airflow/operators/trigger_dagrun.py", line 155, in execute
    replace_microseconds=False,
  File "/home/airflow/.local/lib/python3.7/site-packages/airflow/api/common/trigger_dag.py", line 128, in trigger_dag
    replace_microseconds=replace_microseconds,
  File "/home/airflow/.local/lib/python3.7/site-packages/airflow/api/common/trigger_dag.py", line 52, in _trigger_dag
    raise DagNotFound(f"Dag id {dag_id} not found")
airflow.exceptions.DagNotFound: Dag id crear_tabla_mysql not found
[2025-03-10T00:05:19.968+0000] {taskinstance.py:1373} INFO - Marking task as UP_FOR_RETRY. dag_id=dag_maestro, task_id=load_csv_to_mysql, execution_date=20250310T000232, start_date=20250310T000518, end_date=20250310T000519
[2025-03-10T00:05:20.035+0000] {standard_task_runner.py:109} ERROR - Failed to execute job 20 for task load_csv_to_mysql (Dag id crear_tabla_mysql not found; 682)
[2025-03-10T00:05:20.074+0000] {local_task_job_runner.py:232} INFO - Task exited with return code 1
[2025-03-10T00:05:20.178+0000] {taskinstance.py:2674} INFO - 0 downstream tasks scheduled from follow-on schedule check
